Workbook

Sheet الرئيسية
B1: 🌱 خدمة براعم — نظام الافتقاد والحضور
B2: ="العام الخدمي "&DAY(الإعدادات!$B$10)&"/"&MONTH(الإعدادات!$B$10)&"/"&YEAR(الإعدادات!$B$10)&" ← "&DAY(الإعدادات!$B$11)&"/"&MONTH(الإعدادات!$B$11)&"/"&YEAR(الإعدادات!$B$11)&" • اجتماع كل "&الإعدادات!$B$12 -> العام الخدمي 1/10/2026 ← 1/10/2027 • اجتماع كل الجمعة
B4: 🧭 التنقل السريع
B5: =HYPERLINK("#'قاعدة البيانات'!C"&MIN(305,6+COUNTA('قاعدة البيانات'!$C$6:$C$305)),"➕ إضافة طفل جديد") -> ➕ إضافة طفل جديد | E5: =HYPERLINK("#'قاعدة البيانات'!A1","📋 قاعدة البيانات") -> 📋 قاعدة البيانات | H5: =HYPERLINK("#'الافتقاد'!A1","📞 الافتقاد") -> 📞 الافتقاد | J5: =HYPERLINK("#'الإعدادات'!A1","⚙️ الإعدادات") -> ⚙️ الإعدادات | L5: =HYPERLINK("#'دليل الاستخدام'!A1","📖 الدليل") -> 📖 الدليل
B7: =HYPERLINK("#'فصل سوريال'!A1","🪪 كروت ملاك سوريال") -> 🪪 كروت ملاك سوريال | E7: =HYPERLINK("#'فصل غبريال'!A1","🪪 كروت ملاك غبريال") -> 🪪 كروت ملاك غبريال | H7: =HYPERLINK("#'فصل رفائيل'!A1","🪪 كروت ملاك رفائيل") -> 🪪 كروت ملاك رفائيل | K7: =HYPERLINK("#'فصل ميخائيل'!A1","🪪 كروت ملاك ميخائيل") -> 🪪 كروت ملاك ميخائيل
B8: =HYPERLINK("#'حضور سوريال'!A1","📅 حضور سوريال") -> 📅 حضور سوريال | E8: =HYPERLINK("#'حضور غبريال'!A1","📅 حضور غبريال") -> 📅 حضور غبريال | H8: =HYPERLINK("#'حضور رفائيل'!A1","📅 حضور رفائيل") -> 📅 حضور رفائيل | K8: =HYPERLINK("#'حضور ميخائيل'!A1","📅 حضور ميخائيل") -> 📅 حضور ميخائيل
B10: 📌 نظرة عامة
B11: 👶 إجمالي الأطفال | D11: 👦 أولاد | F11: 👧 بنات | H11: 📈 نسبة الحضور العامة | J11: ⚠️ محتاجين افتقاد | L11: 🗓️ آخر جمعة مسجلة
B12: =COUNTIFS('قاعدة البيانات'!$C$6:$C$305,"<>",'قاعدة البيانات'!$M$6:$M$305,"<>غير نشط") -> 85 | D12: =COUNTIFS('قاعدة البيانات'!$D$6:$D$305,"ولد",'قاعدة البيانات'!$C$6:$C$305,"<>",'قاعدة البيانات'!$M$6:$M$305,"<>غير نشط") -> 42 | F12: =COUNTIFS('قاعدة البيانات'!$D$6:$D$305,"بنت",'قاعدة البيانات'!$C$6:$C$305,"<>",'قاعدة البيانات'!$M$6:$M$305,"<>غير نشط") -> 43 | H12: =IFERROR((SUM('حضور سوريال'!C7:C36)+SUM('حضور غبريال'!C7:C36)+SUM('حضور رفائيل'!C7:C36)+SUM('حضور ميخائيل'!C7:C36))/((SUM('حضور سوريال'!C7:C36)+SUM('حضور غبريال'!C7:C36)+SUM('حضور رفائيل'!C7:C36)+SUM('حضور ميخائيل'!C7:C36))+(SUM('حضور سوريال'!D7:D36)+SUM('حضور غبريال'!D7:D36)+SUM('حضور رفائيل'!D7:D36)+SUM('حضور ميخائيل'!D7:D36))),"—") -> — | J12: =COUNT('قاعدة البيانات'!$W$6:$W$305) -> 0 | L12: =IF(MAX(IFERROR(LOOKUP(2,1/ISNUMBER('حضور سوريال'!J4:BJ4),'حضور سوريال'!J6:BJ6),0),IFERROR(LOOKUP(2,1/ISNUMBER('حضور غبريال'!J4:BJ4),'حضور غبريال'!J6:BJ6),0),IFERROR(LOOKUP(2,1/ISNUMBER('حضور رفائيل'!J4:BJ4),'حضور رفائيل'!J6:BJ6),0),IFERROR(LOOKUP(2,1/ISNUMBER('حضور ميخائيل'!J4:BJ4),'حضور ميخائيل'!J6:BJ6),0))=0,"—",MAX(IFERROR(LOOKUP(2,1/ISNUMBER('حضور سوريال'!J4:BJ4),'حضور سوريال'!J6:BJ6),0),IFERROR(LOOKUP(2,1/ISNUMBER('حضور غبريال'!J4:BJ4),'حضور غبريال'!J6:BJ6),0),IFERROR(LOOKUP(2,1/ISNUMBER('حضور رفائيل'!J4:BJ4),'حضور رفائيل'!J6:BJ6),0),IFERROR(LOOKUP(2,1/ISNUMBER('حضور ميخائيل'!J4:BJ4),'حضور ميخائيل'!J6:BJ6),0))) -> —
B14: 📊 ملخص الفصول
B15: الفصل | D15: الأطفال | E15: أولاد | F15: بنات | G15: نسبة الحضور | I15: محتاجين افتقاد | K15: حالة السعة
B16: =الإعدادات!$B$4 -> سوريال | D16: =COUNTIFS('قاعدة البيانات'!$F$6:$F$305,الإعدادات!$B$4,'قاعدة البيانات'!$C$6:$C$305,"<>",'قاعدة البيانات'!$M$6:$M$305,"<>غير نشط") -> 24 | E16: =COUNTIFS('قاعدة البيانات'!$F$6:$F$305,الإعدادات!$B$4,'قاعدة البيانات'!$D$6:$D$305,"ولد",'قاعدة البيانات'!$C$6:$C$305,"<>",'قاعدة البيانات'!$M$6:$M$305,"<>غير نشط") -> 13 | F16: =COUNTIFS('قاعدة البيانات'!$F$6:$F$305,الإعدادات!$B$4,'قاعدة البيانات'!$D$6:$D$305,"بنت",'قاعدة البيانات'!$C$6:$C$305,"<>",'قاعدة البيانات'!$M$6:$M$305,"<>غير نشط") -> 11 | G16: =IFERROR(SUM('حضور سوريال'!C7:C36)/(SUM('حضور سوريال'!C7:C36)+SUM('حضور سوريال'!D7:D36)),"—") -> — | I16: =COUNTIFS('قاعدة البيانات'!$F$6:$F$305,الإعدادات!$B$4,'قاعدة البيانات'!$V$6:$V$305,3)+COUNTIFS('قاعدة البيانات'!$F$6:$F$305,الإعدادات!$B$4,'قاعدة البيانات'!$V$6:$V$305,4) -> 0 | K16: =IF(COUNTIFS('قاعدة البيانات'!$F$6:$F$305,الإعدادات!$B$4,'قاعدة البيانات'!$C$6:$C$305,"<>")>30,"⚠️ زيادة عن 30 — الزيادة مش هتظهر","✅ "&(30-COUNTIFS('قاعدة البيانات'!$F$6:$F$305,الإعدادات!$B$4,'قاعدة البيانات'!$C$6:$C$305,"<>"))&" مكان فاضي") -> ✅ 6 مكان فاضي
B17: =الإعدادات!$B$5 -> غبريال | D17: =COUNTIFS('قاعدة البيانات'!$F$6:$F$305,الإعدادات!$B$5,'قاعدة البيانات'!$C$6:$C$305,"<>",'قاعدة البيانات'!$M$6:$M$305,"<>غير نشط") -> 24 | E17: =COUNTIFS('قاعدة البيانات'!$F$6:$F$305,الإعدادات!$B$5,'قاعدة البيانات'!$D$6:$D$305,"ولد",'قاعدة البيانات'!$C$6:$C$305,"<>",'قاعدة البيانات'!$M$6:$M$305,"<>غير نشط") -> 10 | F17: =COUNTIFS('قاعدة البيانات'!$F$6:$F$305,الإعدادات!$B$5,'قاعدة البيانات'!$D$6:$D$305,"بنت",'قاعدة البيانات'!$C$6:$C$305,"<>",'قاعدة البيانات'!$M$6:$M$305,"<>غير نشط") -> 14 | G17: =IFERROR(SUM('حضور غبريال'!C7:C36)/(SUM('حضور غبريال'!C7:C36)+SUM('حضور غبريال'!D7:D36)),"—") -> — | I17: =COUNTIFS('قاعدة البيانات'!$F$6:$F$305,الإعدادات!$B$5,'قاعدة البيانات'!$V$6:$V$305,3)+COUNTIFS('قاعدة البيانات'!$F$6:$F$305,الإعدادات!$B$5,'قاعدة البيانات'!$V$6:$V$305,4) -> 0 | K17: =IF(COUNTIFS('قاعدة البيانات'!$F$6:$F$305,الإعدادات!$B$5,'قاعدة البيانات'!$C$6:$C$305,"<>")>30,"⚠️ زيادة عن 30 — الزيادة مش هتظهر","✅ "&(30-COUNTIFS('قاعدة البيانات'!$F$6:$F$305,الإعدادات!$B$5,'قاعدة البيانات'!$C$6:$C$305,"<>"))&" مكان فاضي") -> ✅ 6 مكان فاضي
B18: =الإعدادات!$B$6 -> رفائيل | D18: =COUNTIFS('قاعدة البيانات'!$F$6:$F$305,الإعدادات!$B$6,'قاعدة البيانات'!$C$6:$C$305,"<>",'قاعدة البيانات'!$M$6:$M$305,"<>غير نشط") -> 17 | E18: =COUNTIFS('قاعدة البيانات'!$F$6:$F$305,الإعدادات!$B$6,'قاعدة البيانات'!$D$6:$D$305,"ولد",'قاعدة البيانات'!$C$6:$C$305,"<>",'قاعدة البيانات'!$M$6:$M$305,"<>غير نشط") -> 8 | F18: =COUNTIFS('قاعدة البيانات'!$F$6:$F$305,الإعدادات!$B$6,'قاعدة البيانات'!$D$6:$D$305,"بنت",'قاعدة البيانات'!$C$6:$C$305,"<>",'قاعدة البيانات'!$M$6:$M$305,"<>غير نشط") -> 9 | G18: =IFERROR(SUM('حضور رفائيل'!C7:C36)/(SUM('حضور رفائيل'!C7:C36)+SUM('حضور رفائيل'!D7:D36)),"—") -> — | I18: =COUNTIFS('قاعدة البيانات'!$F$6:$F$305,الإعدادات!$B$6,'قاعدة البيانات'!$V$6:$V$305,3)+COUNTIFS('قاعدة البيانات'!$F$6:$F$305,الإعدادات!$B$6,'قاعدة البيانات'!$V$6:$V$305,4) -> 0 | K18: =IF(COUNTIFS('قاعدة البيانات'!$F$6:$F$305,الإعدادات!$B$6,'قاعدة البيانات'!$C$6:$C$305,"<>")>30,"⚠️ زيادة عن 30 — الزيادة مش هتظهر","✅ "&(30-COUNTIFS('قاعدة البيانات'!$F$6:$F$305,الإعدادات!$B$6,'قاعدة البيانات'!$C$6:$C$305,"<>"))&" مكان فاضي") -> ✅ 13 مكان فاضي
B19: =الإعدادات!$B$7 -> ميخائيل | D19: =COUNTIFS('قاعدة البيانات'!$F$6:$F$305,الإعدادات!$B$7,'قاعدة البيانات'!$C$6:$C$305,"<>",'قاعدة البيانات'!$M$6:$M$305,"<>غير نشط") -> 20 | E19: =COUNTIFS('قاعدة البيانات'!$F$6:$F$305,الإعدادات!$B$7,'قاعدة البيانات'!$D$6:$D$305,"ولد",'قاعدة البيانات'!$C$6:$C$305,"<>",'قاعدة البيانات'!$M$6:$M$305,"<>غير نشط") -> 11 | F19: =COUNTIFS('قاعدة البيانات'!$F$6:$F$305,الإعدادات!$B$7,'قاعدة البيانات'!$D$6:$D$305,"بنت",'قاعدة البيانات'!$C$6:$C$305,"<>",'قاعدة البيانات'!$M$6:$M$305,"<>غير نشط") -> 9 | G19: =IFERROR(SUM('حضور ميخائيل'!C7:C36)/(SUM('حضور ميخائيل'!C7:C36)+SUM('حضور ميخائيل'!D7:D36)),"—") -> — | I19: =COUNTIFS('قاعدة البيانات'!$F$6:$F$305,الإعدادات!$B$7,'قاعدة البيانات'!$V$6:$V$305,3)+COUNTIFS('قاعدة البيانات'!$F$6:$F$305,الإعدادات!$B$7,'قاعدة البيانات'!$V$6:$V$305,4) -> 0 | K19: =IF(COUNTIFS('قاعدة البيانات'!$F$6:$F$305,الإعدادات!$B$7,'قاعدة البيانات'!$C$6:$C$305,"<>")>30,"⚠️ زيادة عن 30 — الزيادة مش هتظهر","✅ "&(30-COUNTIFS('قاعدة البيانات'!$F$6:$F$305,الإعدادات!$B$7,'قاعدة البيانات'!$C$6:$C$305,"<>"))&" مكان فاضي") -> ✅ 10 مكان فاضي
B20: الإجمالي | D20: =SUM(D16:D19) -> 85 | E20: =SUM(E16:E19) -> 42 | F20: =SUM(F16:F19) -> 43 | G20: =IFERROR((SUM('حضور سوريال'!C7:C36)+SUM('حضور غبريال'!C7:C36)+SUM('حضور رفائيل'!C7:C36)+SUM('حضور ميخائيل'!C7:C36))/((SUM('حضور سوريال'!C7:C36)+SUM('حضور غبريال'!C7:C36)+SUM('حضور رفائيل'!C7:C36)+SUM('حضور ميخائيل'!C7:C36))+(SUM('حضور سوريال'!D7:D36)+SUM('حضور غبريال'!D7:D36)+SUM('حضور رفائيل'!D7:D36)+SUM('حضور ميخائيل'!D7:D36))),"—") -> — | I20: =SUM(I16:I19) -> 0

Sheet قاعدة البيانات
A1: 📋 قاعدة بيانات الأطفال
A2: =HYPERLINK("#'الرئيسية'!A1","🏠 الرئيسية") -> 🏠 الرئيسية | C2: =HYPERLINK("#'قاعدة البيانات'!C"&MIN(305,6+COUNTA('قاعدة البيانات'!$C$6:$C$305)),"➕ إضافة طفل جديد") -> ➕ إضافة طفل جديد | D2: =HYPERLINK("#'الافتقاد'!A1","📞 الافتقاد") -> 📞 الافتقاد | G2: =HYPERLINK("#'فصل سوريال'!A1","🪪 سوريال") -> 🪪 سوريال | H2: =HYPERLINK("#'فصل غبريال'!A1","🪪 غبريال") -> 🪪 غبريال | I2: =HYPERLINK("#'فصل رفائيل'!A1","🪪 رفائيل") -> 🪪 رفائيل | J2: =HYPERLINK("#'فصل ميخائيل'!A1","🪪 ميخائيل") -> 🪪 ميخائيل | K2: =HYPERLINK("#'الإعدادات'!A1","⚙️ الإعدادات") -> ⚙️ الإعدادات | M2: =HYPERLINK("#'دليل الاستخدام'!A1","📖 دليل الاستخدام") -> 📖 دليل الاستخدام
A3: ="👶 المسجلين: "&COUNTA(C6:C305)&" ✅ نشط: "&COUNTIFS(C6:C305,"<>",M6:M305,"<>غير نشط")&" 🆓 صفوف فاضية: "&(300-COUNTA(C6:C305)) -> 👶 المسجلين: 85 ✅ نشط: 85 🆓 صفوف فاضية: 215
A4: ✍️ اكتب بيانات الطفل في أول صف فاضي (الخانات البيضاء من «الاسم» لـ «الحالة») — الأعمدة الرمادية الغامقة بتتحسب لوحدها. الطفل بيظهر أوتوماتيك في كارت فصله وفي قايمة الحضور. ⚠️ ماتمسحش صفوف ولا تعمل Sort — استخدم «غير نشط».
A5: م | B5: الكود | C5: الاسم | D5: النوع | E5: السنة الدراسية | F5: الفصل (الملاك) | G5: يروح لوحده؟ | H5: رقم الأم | I5: رقم الأب | J5: العنوان | K5: الصورة 📷 | L5: ملاحظات | M5: الحالة | N5: مفتاح | O5: ترتيب | P5: حضور ✅ | Q5: غياب ❌ | R5: النسبة | S5: غياب متتالي | T5: آخر حضور | U5: حالة الحضور | V5: tier | W5: فهرس
A6: =IF(C6="","",ROW()-5) -> 1 | B6: =IF(C6="","","B-"&TEXT(ROW()-5,"000")) -> B-001 | C6: توماس صابر صبحى | D6: ولد | E6: سنة تانية | F6: غبريال | G6: لا | H6: 01271325124 | J6: 58 شارع ترعة حمزة - شقة 6 الدور 3 - يمين السلم | K6: #VALUE! | M6: نشط | N6: =IF(O6="","",F6&"|"&O6) -> غبريال|1 | O6: =IF(OR(C6="",F6=""),"",COUNTIFS(F$6:F6,F6,C$6:C6,"<>")) -> 1 | P6: =IF($O6="","",IFERROR(CHOOSE(MATCH($F6,الإعدادات!$B$4:$B$7,0),INDEX('حضور سوريال'!$C$7:$C$36,$O6),INDEX('حضور غبريال'!$C$7:$C$36,$O6),INDEX('حضور رفائيل'!$C$7:$C$36,$O6),INDEX('حضور ميخائيل'!$C$7:$C$36,$O6)),"")) -> 0 | Q6: =IF($O6="","",IFERROR(CHOOSE(MATCH($F6,الإعدادات!$B$4:$B$7,0),INDEX('حضور سوريال'!$D$7:$D$36,$O6),INDEX('حضور غبريال'!$D$7:$D$36,$O6),INDEX('حضور رفائيل'!$D$7:$D$36,$O6),INDEX('حضور ميخائيل'!$D$7:$D$36,$O6)),"")) -> 0 | R6: =IF($O6="","",IFERROR(CHOOSE(MATCH($F6,الإعدادات!$B$4:$B$7,0),INDEX('حضور سوريال'!$F$7:$F$36,$O6),INDEX('حضور غبريال'!$F$7:$F$36,$O6),INDEX('حضور رفائيل'!$F$7:$F$36,$O6),INDEX('حضور ميخائيل'!$F$7:$F$36,$O6)),"")) | S6: =IF($O6="","",IFERROR(CHOOSE(MATCH($F6,الإعدادات!$B$4:$B$7,0),INDEX('حضور سوريال'!$G$7:$G$36,$O6),INDEX('حضور غبريال'!$G$7:$G$36,$O6),INDEX('حضور رفائيل'!$G$7:$G$36,$O6),INDEX('حضور ميخائيل'!$G$7:$G$36,$O6)),"")) -> 0 | T6: =IF($O6="","",IFERROR(CHOOSE(MATCH($F6,الإعدادات!$B$4:$B$7,0),INDEX('حضور سوريال'!$H$7:$H$36,$O6),INDEX('حضور غبريال'!$H$7:$H$36,$O6),INDEX('حضور رفائيل'!$H$7:$H$36,$O6),INDEX('حضور ميخائيل'!$H$7:$H$36,$O6)),"")) -> — | U6: =IF($O6="","",IFERROR(CHOOSE(MATCH($F6,الإعدادات!$B$4:$B$7,0),INDEX('حضور سوريال'!$I$7:$I$36,$O6),INDEX('حضور غبريال'!$I$7:$I$36,$O6),INDEX('حضور رفائيل'!$I$7:$I$36,$O6),INDEX('حضور ميخائيل'!$I$7:$I$36,$O6)),"")) -> ⏳ لسه مفيش حضور | V6: =IF($O6="","",IFERROR(CHOOSE(MATCH($F6,الإعدادات!$B$4:$B$7,0),INDEX('حضور سوريال'!$BM$7:$BM$36,$O6),INDEX('حضور غبريال'!$BM$7:$BM$36,$O6),INDEX('حضور رفائيل'!$BM$7:$BM$36,$O6),INDEX('حضور ميخائيل'!$BM$7:$BM$36,$O6)),"")) -> 0 | W6: =IF(OR(V6=3,V6=4),COUNTIFS(V$6:V6,3)+COUNTIFS(V$6:V6,4),"")
A7: =IF(C7="","",ROW()-5) -> 2 | B7: =IF(C7="","","B-"&TEXT(ROW()-5,"000")) -> B-002 | C7: سيلينا رامي رومانى | D7: بنت | E7: سنة تانية | F7: غبريال | G7: لا | H7: 01286806532 | J7: 115 أ ابراج الاصاله امام الصحة - الدور ال 12 الشقة اللي علي اليمين - براج الاصاله امام الصحة الدور ال 12 الشقه على اليمين اول عمارة على الشمال | K7: #VALUE! | M7: نشط | N7: =IF(O7="","",F7&"|"&O7) -> غبريال|2 | O7: =IF(OR(C7="",F7=""),"",COUNTIFS(F$6:F7,F7,C$6:C7,"<>")) -> 2 | P7: =IF($O7="","",IFERROR(CHOOSE(MATCH($F7,الإعدادات!$B$4:$B$7,0),INDEX('حضور سوريال'!$C$7:$C$36,$O7),INDEX('حضور غبريال'!$C$7:$C$36,$O7),INDEX('حضور رفائيل'!$C$7:$C$36,$O7),INDEX('حضور ميخائيل'!$C$7:$C$36,$O7)),"")) -> 0 | Q7: =IF($O7="","",IFERROR(CHOOSE(MATCH($F7,الإعدادات!$B$4:$B$7,0),INDEX('حضور سوريال'!$D$7:$D$36,$O7),INDEX('حضور غبريال'!$D$7:$D$36,$O7),INDEX('حضور رفائيل'!$D$7:$D$36,$O7),INDEX('حضور ميخائيل'!$D$7:$D$36,$O7)),"")) -> 0 | R7: =IF($O7="","",IFERROR(CHOOSE(MATCH($F7,الإعدادات!$B$4:$B$7,0),INDEX('حضور سوريال'!$F$7:$F$36,$O7),INDEX('حضور غبريال'!$F$7:$F$36,$O7),INDEX('حضور رفائيل'!$F$7:$F$36,$O7),INDEX('حضور ميخائيل'!$F$7:$F$36,$O7)),"")) | S7: =IF($O7="","",IFERROR(CHOOSE(MATCH($F7,الإعدادات!$B$4:$B$7,0),INDEX('حضور سوريال'!$G$7:$G$36,$O7),INDEX('حضور غبريال'!$G$7:$G$36,$O7),INDEX('حضور رفائيل'!$G$7:$G$36,$O7),INDEX('حضور ميخائيل'!$G$7:$G$36,$O7)),"")) -> 0 | T7: =IF($O7="","",IFERROR(CHOOSE(MATCH($F7,الإعدادات!$B$4:$B$7,0),INDEX('حضور سوريال'!$H$7:$H$36,$O7),INDEX('حضور غبريال'!$H$7:$H$36,$O7),INDEX('حضور رفائيل'!$H$7:$H$36,$O7),INDEX('حضور ميخائيل'!$H$7:$H$36,$O7)),"")) -> — | U7: =IF($O7="","",IFERROR(CHOOSE(MATCH($F7,الإعدادات!$B$4:$B$7,0),INDEX('حضور سوريال'!$I$7:$I$36,$O7),INDEX('حضور غبريال'!$I$7:$I$36,$O7),INDEX('حضور رفائيل'!$I$7:$I$36,$O7),INDEX('حضور ميخائيل'!$I$7:$I$36,$O7)),"")) -> ⏳ لسه مفيش حضور | V7: =IF($O7="","",IFERROR(CHOOSE(MATCH($F7,الإعدادات!$B$4:$B$7,0),INDEX('حضور سوريال'!$BM$7:$BM$36,$O7),INDEX('حضور غبريال'!$BM$7:$BM$36,$O7),INDEX('حضور رفائيل'!$BM$7:$BM$36,$O7),INDEX('حضور ميخائيل'!$BM$7:$BM$36,$O7)),"")) -> 0 | W7: =IF(OR(V7=3,V7=4),COUNTIFS(V$6:V7,3)+COUNTIFS(V$6:V7,4),"")
A8: =IF(C8="","",ROW()-5) -> 3 | B8: =IF(C8="","","B-"&TEXT(ROW()-5,"000")) -> B-003 | C8: روبن عبد المسيح رافت | D8: ولد | E8: سنة تانية | F8: غبريال | G8: لا | H8: 01227832577 | I8: 01221561038 | J8: 8 شارع محمد مغاورى - شقة 5 الدور 5 - من شارع البشري / الشارع اللى قدام محل بيبو | K8: #VALUE! | M8: نشط | N8: =IF(O8="","",F8&"|"&O8) -> غبريال|3 | O8: =IF(OR(C8="",F8=""),"",COUNTIFS(F$6:F8,F8,C$6:C8,"<>")) -> 3 | P8: =IF($O8="","",IFERROR(CHOOSE(MATCH($F8,الإعدادات!$B$4:$B$7,0),INDEX('حضور سوريال'!$C$7:$C$36,$O8),INDEX('حضور غبريال'!$C$7:$C$36,$O8),INDEX('حضور رفائيل'!$C$7:$C$36,$O8),INDEX('حضور ميخائيل'!$C$7:$C$36,$O8)),"")) -> 0 | Q8: =IF($O8="","",IFERROR(CHOOSE(MATCH($F8,الإعدادات!$B$4:$B$7,0),INDEX('حضور سوريال'!$D$7:$D$36,$O8),INDEX('حضور غبريال'!$D$7:$D$36,$O8),INDEX('حضور رفائيل'!$D$7:$D$36,$O8),INDEX('حضور ميخائيل'!$D$7:$D$36,$O8)),"")) -> 0 | R8: =IF($O8="","",IFERROR(CHOOSE(MATCH($F8,الإعدادات!$B$4:$B$7,0),INDEX('حضور سوريال'!$F$7:$F$36,$O8),INDEX('حضور غبريال'!$F$7:$F$36,$O8),INDEX('حضور رفائيل'!$F$7:$F$36,$O8),INDEX('حضور ميخائيل'!$F$7:$F$36,$O8)),"")) | S8: =IF($O8="","",IFERROR(CHOOSE(MATCH($F8,الإعدادات!$B$4:$B$7,0),INDEX('حضور سوريال'!$G$7:$G$36,$O8),INDEX('حضور غبريال'!$G$7:$G$36,$O8),INDEX('حضور رفائيل'!$G$7:$G$36,$O8),INDEX('حضور ميخائيل'!$G$7:$G$36,$O8)),"")) -> 0 | T8: =IF($O8="","",IFERROR(CHOOSE(MATCH($F8,الإعدادات!$B$4:$B$7,0),INDEX('حضور سوريال'!$H$7:$H$36,$O8),INDEX('حضور غبريال'!$H$7:$H$36,$O8),INDEX('حضور رفائيل'!$H$7:$H$36,$O8),INDEX('حضور ميخائيل'!$H$7:$H$36,$O8)),"")) -> — | U8: =IF($O8="","",IFERROR(CHOOSE(MATCH($F8,الإعدادات!$B$4:$B$7,0),INDEX('حضور سوريال'!$I$7:$I$36,$O8),INDEX('حضور غبريال'!$I$7:$I$36,$O8),INDEX('حضور رفائيل'!$I$7:$I$36,$O8),INDEX('حضور ميخائيل'!$I$7:$I$36,$O8)),"")) -> ⏳ لسه مفيش حضور | V8: =IF($O8="","",IFERROR(CHOOSE(MATCH($F8,الإعدادات!$B$4:$B$7,0),INDEX('حضور سوريال'!$BM$7:$BM$36,$O8),INDEX('حضور غبريال'!$BM$7:$BM$36,$O8),INDEX('حضور رفائيل'!$BM$7:$BM$36,$O8),INDEX('حضور ميخائيل'!$BM$7:$BM$36,$O8)),"")) -> 0 | W8: =IF(OR(V8=3,V8=4),COUNTIFS(V$6:V8,3)+COUNTIFS(V$6:V8,4),"")
A9: =IF(C9="","",ROW()-5) -> 4 | B9: =IF(C9="","","B-"&TEXT(ROW()-5,"000")) -> B-004 | C9: جوى جورج ثابت | D9: بنت | E9: سنة تانية | F9: غبريال | G9: لا | H9: 01228872241 | J9: 5 شارع البشرى المليحة - صيدلية ميشيل | M9: نشط | N9: =IF(O9="","",F9&"|"&O9) -> غبريال|4 | O9: =IF(OR(C9="",F9=""),"",COUNTIFS(F$6:F9,F9,C$6:C9,"<>")) -> 4 | P9: =IF($O9="","",IFERROR(CHOOSE(MATCH($F9,الإعدادات!$B$4:$B$7,0),INDEX('حضور سوريال'!$C$7:$C$36,$O9),INDEX('حضور غبريال'!$C$7:$C$36,$O9),INDEX('حضور رفائيل'!$C$7:$C$36,$O9),INDEX('حضور ميخائيل'!$C$7:$C$36,$O9)),"")) -> 0 | Q9: =IF($O9="","",IFERROR(CHOOSE(MATCH($F9,الإعدادات!$B$4:$B$7,0),INDEX('حضور سوريال'!$D$7:$D$36,$O9),INDEX('حضور غبريال'!$D$7:$D$36,$O9),INDEX('حضور رفائيل'!$D$7:$D$36,$O9),INDEX('حضور ميخائيل'!$D$7:$D$36,$O9)),"")) -> 0 | R9: =IF($O9="","",IFERROR(CHOOSE(MATCH($F9,الإعدادات!$B$4:$B$7,0),INDEX('حضور سوريال'!$F$7:$F$36,$O9),INDEX('حضور غبريال'!$F$7:$F$36,$O9),INDEX('حضور رفائيل'!$F$7:$F$36,$O9),INDEX('حضور ميخائيل'!$F$7:$F$36,$O9)),"")) | S9: =IF($O9="","",IFERROR(CHOOSE(MATCH($F9,الإعدادات!$B$4:$B$7,0),INDEX('حضور سوريال'!$G$7:$G$36,$O9),INDEX('حضور غبريال'!$G$7:$G$36,$O9),INDEX('حضور رفائيل'!$G$7:$G$36,$O9),INDEX('حضور ميخائيل'!$G$7:$G$36,$O9)),"")) -> 0 | T9: =IF($O9="","",IFERROR(CHOOSE(MATCH($F9,الإعدادات!$B$4:$B$7,0),INDEX('حضور سوريال'!$H$7:$H$36,$O9),INDEX('حضور غبريال'!$H$7:$H$36,$O9),INDEX('حضور رفائيل'!$H$7:$H$36,$O9),INDEX('حضور ميخائيل'!$H$7:$H$36,$O9)),"")) -> — | U9: =IF($O9="","",IFERROR(CHOOSE(MATCH($F9,الإعدادات!$B$4:$B$7,0),INDEX('حضور سوريال'!$I$7:$I$36,$O9),INDEX('حضور غبريال'!$I$7:$I$36,$O9),INDEX('حضور رفائيل'!$I$7:$I$36,$O9),INDEX('حضور ميخائيل'!$I$7:$I$36,$O9)),"")) -> ⏳ لسه مفيش حضور | V9: =IF($O9="","",IFERROR(CHOOSE(MATCH($F9,الإعدادات!$B$4:$B$7,0),INDEX('حضور سوريال'!$BM$7:$BM$36,$O9),INDEX('حضور غبريال'!$BM$7:$BM$36,$O9),INDEX('حضور رفائيل'!$BM$7:$BM$36,$O9),INDEX('حضور ميخائيل'!$BM$7:$BM$36,$O9)),"")) -> 0 | W9: =IF(OR(V9=3,V9=4),COUNTIFS(V$6:V9,3)+COUNTIFS(V$6:V9,4),"")
A10: =IF(C10="","",ROW()-5) -> 5 | B10: =IF(C10="","","B-"&TEXT(ROW()-5,"000")) -> B-005 | C10: بارثينيا رامز منير شفيق | D10: بنت | E10: سنة تانية | F10: غبريال | G10: لا | H10: 01270484412 | J10: 19 شارع عزبة الرشيدى - الدور 7 - عزبه النخل / 19 رشدى نساك | K10: #VALUE! | M10: نشط | N10: =IF(O10="","",F10&"|"&O10) -> غبريال|5 | O10: =IF(OR(C10="",F10=""),"",COUNTIFS(F$6:F10,F10,C$6:C10,"<>")) -> 5 | P10: =IF($O10="","",IFERROR(CHOOSE(MATCH($F10,الإعدادات!$B$4:$B$7,0),INDEX('حضور سوريال'!$C$7:$C$36,$O10),INDEX('حضور غبريال'!$C$7:$C$36,$O10),INDEX('حضور رفائيل'!$C$7:$C$36,$O10),INDEX('حضور ميخائيل'!$C$7:$C$36,$O10)),"")) -> 0 | Q10: =IF($O10="","",IFERROR(CHOOSE(MATCH($F10,الإعدادات!$B$4:$B$7,0),INDEX('حضور سوريال'!$D$7:$D$36,$O10),INDEX('حضور غبريال'!$D$7:$D$36,$O10),INDEX('حضور رفائيل'!$D$7:$D$36,$O10),INDEX('حضور ميخائيل'!$D$7:$D$36,$O10)),"")) -> 0 | R10: =IF($O10="","",IFERROR(CHOOSE(MATCH($F10,الإعدادات!$B$4:$B$7,0),INDEX('حضور سوريال'!$F$7:$F$36,$O10),INDEX('حضور غبريال'!$F$7:$F$36,$O10),INDEX('حضور رفائيل'!$F$7:$F$36,$O10),INDEX('حضور ميخائيل'!$F$7:$F$36,$O10)),"")) | S10: =IF($O10="","",IFERROR(CHOOSE(MATCH($F10,الإعدادات!$B$4:$B$7,0),INDEX('حضور سوريال'!$G$7:$G$36,$O10),INDEX('حضور غبريال'!$G$7:$G$36,$O10),INDEX('حضور رفائيل'!$G$7:$G$36,$O10),INDEX('حضور ميخائيل'!$G$7:$G$36,$O10)),"")) -> 0 | T10: =IF($O10="","",IFERROR(CHOOSE(MATCH($F10,الإعدادات!$B$4:$B$7,0),INDEX('حضور سوريال'!$H$7:$H$36,$O10),INDEX('حضور غبريال'!$H$7:$H$36,$O10),INDEX('حضور رفائيل'!$H$7:$H$36,$O10),INDEX('حضور ميخائيل'!$H$7:$H$36,$O10)),"")) -> — | U10: =IF($O10="","",IFERROR(CHOOSE(MATCH($F10,الإعدادات!$B$4:$B$7,0),INDEX('حضور سوريال'!$I$7:$I$36,$O10),INDEX('حضور غبريال'!$I$7:$I$36,$O10),INDEX('حضور رفائيل'!$I$7:$I$36,$O10),INDEX('حضور ميخائيل'!$I$7:$I$36,$O10)),"")) -> ⏳ لسه مفيش حضور | V10: =IF($O10="","",IFERROR(CHOOSE(MATCH($F10,الإعدادات!$B$4:$B$7,0),INDEX('حضور سوريال'!$BM$7:$BM$36,$O10),INDEX('حضور غبريال'!$BM$7:$BM$36,$O10),INDEX('حضور رفائيل'!$BM$7:$BM$36,$O10),INDEX('حضور ميخائيل'!$BM$7:$BM$36,$O10)),"")) -> 0 | W10: =IF(OR(V10=3,V10=4),COUNTIFS(V$6:V10,3)+COUNTIFS(V$6:V10,4),"")
A11: =IF(C11="","",ROW()-5) -> 6 | B11: =IF(C11="","","B-"&TEXT(ROW()-5,"000")) -> B-006 | C11: مينا رفيق زكريا عبد الشهيد | D11: ولد | E11: سنة تانية | F11: غبريال | G11: لا | H11: 01287449133 | J11: 2 شارع فايز مترى - شقة 1 - الأرضي / مجدى البقال | M11: نشط | N11: =IF(O11="","",F11&"|"&O11) -> غبريال|6 | O11: =IF(OR(C11="",F11=""),"",COUNTIFS(F$6:F11,F11,C$6:C11,"<>")) -> 6 | P11: =IF($O11="","",IFERROR(CHOOSE(MATCH($F11,الإعدادات!$B$4:$B$7,0),INDEX('حضور سوريال'!$C$7:$C$36,$O11),INDEX('حضور غبريال'!$C$7:$C$36,$O11),INDEX('حضور رفائيل'!$C$7:$C$36,$O11),INDEX('حضور ميخائيل'!$C$7:$C$36,$O11)),"")) -> 0 | Q11: =IF($O11="","",IFERROR(CHOOSE(MATCH($F11,الإعدادات!$B$4:$B$7,0),INDEX('حضور سوريال'!$D$7:$D$36,$O11),INDEX('حضور غبريال'!$D$7:$D$36,$O11),INDEX('حضور رفائيل'!$D$7:$D$36,$O11),INDEX('حضور ميخائيل'!$D$7:$D$36,$O11)),"")) -> 0 | R11: =IF($O11="","",IFERROR(CHOOSE(MATCH($F11,الإعدادات!$B$4:$B$7,0),INDEX('حضور سوريال'!$F$7:$F$36,$O11),INDEX('حضور غبريال'!$F$7:$F$36,$O11),INDEX('حضور رفائيل'!$F$7:$F$36,$O11),INDEX('حضور ميخائيل'!$F$7:$F$36,$O11)),"")) | S11: =IF($O11="","",IFERROR(CHOOSE(MATCH($F11,الإعدادات!$B$4:$B$7,0),INDEX('حضور سوريال'!$G$7:$G$36,$O11),INDEX('حضور غبريال'!$G$7:$G$36,$O11),INDEX('حضور رفائيل'!$G$7:$G$36,$O11),INDEX('حضور ميخائيل'!$G$7:$G$36,$O11)),"")) -> 0 | T11: =IF($O11="","",IFERROR(CHOOSE(MATCH($F11,الإعدادات!$B$4:$B$7,0),INDEX('حضور سوريال'!$H$7:$H$36,$O11),INDEX('حضور غبريال'!$H$7:$H$36,$O11),INDEX('حضور رفائيل'!$H$7:$H$36,$O11),INDEX('حضور ميخائيل'!$H$7:$H$36,$O11)),"")) -> — | U11: =IF($O11="","",IFERROR(CHOOSE(MATCH($F11,الإعدادات!$B$4:$B$7,0),INDEX('حضور سوريال'!$I$7:$I$36,$O11),INDEX('حضور غبريال'!$I$7:$I$36,$O11),INDEX('حضور رفائيل'!$I$7:$I$36,$O11),INDEX('حضور ميخائيل'!$I$7:$I$36,$O11)),"")) -> ⏳ لسه مفيش حضور | V11: =IF($O11="","",IFERROR(CHOOSE(MATCH($F11,الإعدادات!$B$4:$B$7,0),INDEX('حضور سوريال'!$BM$7:$BM$36,$O11),INDEX('حضور غبريال'!$BM$7:$BM$36,$O11),INDEX('حضور رفائيل'!$BM$7:$BM$36,$O11),INDEX('حضور ميخائيل'!$BM$7:$BM$36,$O11)),"")) -> 0 | W11: =IF(OR(V11=3,V11=4),COUNTIFS(V$6:V11,3)+COUNTIFS(V$6:V11,4),"")
A12: =IF(C12="","",ROW()-5) -> 7 | B12: =IF(C12="","","B-"&TEXT(ROW()-5,"000")) -> B-007 | C12: بولا غالى توفيق | D12: ولد | E12: سنة تانية | F12: غبريال | G12: لا | H12: 01201247688 | I12: 01206588362 | J12: 25 شارع عبد الشافى حسن | M12: نشط | N12: =IF(O12="","",F12&"|"&O12) -> غبريال|7 | O12: =IF(OR(C12="",F12=""),"",COUNTIFS(F$6:F12,F12,C$6:C12,"<>")) -> 7 | P12: =IF($O12="","",IFERROR(CHOOSE(MATCH($F12,الإعدادات!$B$4:$B$7,0),INDEX('حضور سوريال'!$C$7:$C$36,$O12),INDEX('حضور غبريال'!$C$7:$C$36,$O12),INDEX('حضور رفائيل'!$C$7:$C$36,$O12),INDEX('حضور ميخائيل'!$C$7:$C$36,$O12)),"")) -> 0 | Q12: =IF($O12="","",IFERROR(CHOOSE(MATCH($F12,الإعدادات!$B$4:$B$7,0),INDEX('حضور سوريال'!$D$7:$D$36,$O12),INDEX('حضور غبريال'!$D$7:$D$36,$O12),INDEX('حضور رفائيل'!$D$7:$D$36,$O12),INDEX('حضور ميخائيل'!$D$7:$D$36,$O12)),"")) -> 0 | R12: =IF($O12="","",IFERROR(CHOOSE(MATCH($F12,الإعدادات!$B$4:$B$7,0),INDEX('حضور سوريال'!$F$7:$F$36,$O12),INDEX('حضور غبريال'!$F$7:$F$36,$O12),INDEX('حضور رفائيل'!$F$7:$F$36,$O12),INDEX('حضور ميخائيل'!$F$7:$F$36,$O12)),"")) | S12: =IF($O12="","",IFERROR(CHOOSE(MATCH($F12,الإعدادات!$B$4:$B$7,0),INDEX('حضور سوريال'!$G$7:$G$36,$O12),INDEX('حضور غبريال'!$G$7:$G$36,$O12),INDEX('حضور رفائيل'!$G$7:$G$36,$O12),INDEX('حضور ميخائيل'!$G$7:$G$36,$O12)),"")) -> 0 | T12: =IF($O12="","",IFERROR(CHOOSE(MATCH($F12,الإعدادات!$B$4:$B$7,0),INDEX('حضور سوريال'!$H$7:$H$36,$O12),INDEX('حضور غبريال'!$H$7:$H$36,$O12),INDEX('حضور رفائيل'!$H$7:$H$36,$O12),INDEX('حضور ميخائيل'!$H$7:$H$36,$O12)),"")) -> — | U12: =IF($O12="","",IFERROR(CHOOSE(MATCH($F12,الإعدادات!$B$4:$B$7,0),INDEX('حضور سوريال'!$I$7:$I$36,$O12),INDEX('حضور غبريال'!$I$7:$I$36,$O12),INDEX('حضور رفائيل'!$I$7:$I$36,$O12),INDEX('حضور ميخائيل'!$I$7:$I$36,$O12)),"")) -> ⏳ لسه مفيش حضور | V12: =IF($O12="","",IFERROR(CHOOSE(MATCH($F12,الإعدادات!$B$4:$B$7,0),INDEX('حضور سوريال'!$BM$7:$BM$36,$O12),INDEX('حضور غبريال'!$BM$7:$BM$36,$O12),INDEX('حضور رفائيل'!$BM$7:$BM$36,$O12),INDEX('حضور ميخائيل'!$BM$7:$BM$36,$O12)),"")) -> 0 | W12: =IF(OR(V12=3,V12=4),COUNTIFS(V$6:V12,3)+COUNTIFS(V$6:V12,4),"")
A13: =IF(C13="","",ROW()-5) -> 8 | B13: =IF(C13="","","B-"&TEXT(ROW()-5,"000")) -> B-008 | C13: ماري جرجس اسحق عطا الله | D13: بنت | E13: سنة تانية | F13: غبريال | G13: لا | H13: 01201652497 | J13: 4 شارع روفائيل سليمان - شقة 85 الدور 11 - امام الاسانسير | K13: #VALUE! | M13: نشط | N13: =IF(O13="","",F13&"|"&O13) -> غبريال|8 | O13: =IF(OR(C13="",F13=""),"",COUNTIFS(F$6:F13,F13,C$6:C13,"<>")) -> 8 | P13: =IF($O13="","",IFERROR(CHOOSE(MATCH($F13,الإعدادات!$B$4:$B$7,0),INDEX('حضور سوريال'!$C$7:$C$36,$O13),INDEX('حضور غبريال'!$C$7:$C$36,$O13),INDEX('حضور رفائيل'!$C$7:$C$36,$O13),INDEX('حضور ميخائيل'!$C$7:$C$36,$O13)),"")) -> 0 | Q13: =IF($O13="","",IFERROR(CHOOSE(MATCH($F13,الإعدادات!$B$4:$B$7,0),INDEX('حضور سوريال'!$D$7:$D$36,$O13),INDEX('حضور غبريال'!$D$7:$D$36,$O13),INDEX('حضور رفائيل'!$D$7:$D$36,$O13),INDEX('حضور ميخائيل'!$D$7:$D$36,$O13)),"")) -> 0 | R13: =IF($O13="","",IFERROR(CHOOSE(MATCH($F13,الإعدادات!$B$4:$B$7,0),INDEX('حضور سوريال'!$F$7:$F$36,$O13),INDEX('حضور غبريال'!$F$7:$F$36,$O13),INDEX('حضور رفائيل'!$F$7:$F$36,$O13),INDEX('حضور ميخائيل'!$F$7:$F$36,$O13)),"")) | S13: =IF($O13="","",IFERROR(CHOOSE(MATCH($F13,الإعدادات!$B$4:$B$7,0),INDEX('حضور سوريال'!$G$7:$G$36,$O13),INDEX('حضور غبريال'!$G$7:$G$36,$O13),INDEX('حضور رفائيل'!$G$7:$G$36,$O13),INDEX('حضور ميخائيل'!$G$7:$G$36,$O13)),"")) -> 0 | T13: =IF($O13="","",IFERROR(CHOOSE(MATCH($F13,الإعدادات!$B$4:$B$7,0),INDEX('حضور سوريال'!$H$7:$H$36,$O13),INDEX('حضور غبريال'!$H$7:$H$36,$O13),INDEX('حضور رفائيل'!$H$7:$H$36,$O13),INDEX('حضور ميخائيل'!$H$7:$H$36,$O13)),"")) -> — | U13: =IF($O13="","",IFERROR(CHOOSE(MATCH($F13,الإعدادات!$B$4:$B$7,0),INDEX('حضور سوريال'!$I$7:$I$36,$O13),INDEX('حضور غبريال'!$I$7:$I$36,$O13),INDEX('حضور رفائيل'!$I$7:$I$36,$O13),INDEX('حضور ميخائيل'!$I$7:$I$36,$O13)),"")) -> ⏳ لسه مفيش حضور | V13: =IF($O13="","",IFERROR(CHOOSE(MATCH($F13,الإعدادات!$B$4:$B$7,0),INDEX('حضور سوريال'!$BM$7:$BM$36,$O13),INDEX('حضور غبريال'!$BM$7:$BM$36,$O13),INDEX('حضور رفائيل'!$BM$7:$BM$36,$O13),INDEX('حضور ميخائيل'!$BM$7:$BM$36,$O13)),"")) -> 0 | W13: =IF(OR(V13=3,V13=4),COUNTIFS(V$6:V13,3)+COUNTIFS(V$6:V13,4),"")
A14: =IF(C14="","",ROW()-5) -> 9 | B14: =IF(C14="","","B-"&TEXT(ROW()-5,"000")) -> B-009 | C14: بيشوى سمير ميخائيل فيلته | D14: ولد | E14: سنة تانية | F14: غبريال | G14: لا | H14: 01208183104 | J14: 10 شارع عطوه حسن - شقة 4 الدور 4 | K14: #VALUE! | M14: نشط | N14: =IF(O14="","",F14&"|"&O14) -> غبريال|9 | O14: =IF(OR(C14="",F14=""),"",COUNTIFS(F$6:F14,F14,C$6:C14,"<>")) -> 9 | P14: =IF($O14="","",IFERROR(CHOOSE(MATCH($F14,الإعدادات!$B$4:$B$7,0),INDEX('حضور سوريال'!$C$7:$C$36,$O14),INDEX('حضور غبريال'!$C$7:$C$36,$O14),INDEX('حضور رفائيل'!$C$7:$C$36,$O14),INDEX('حضور ميخائيل'!$C$7:$C$36,$O14)),"")) -> 0 | Q14: =IF($O14="","",IFERROR(CHOOSE(MATCH($F14,الإعدادات!$B$4:$B$7,0),INDEX('حضور سوريال'!$D$7:$D$36,$O14),INDEX('حضور غبريال'!$D$7:$D$36,$O14),INDEX('حضور رفائيل'!$D$7:$D$36,$O14),INDEX('حضور ميخائيل'!$D$7:$D$36,$O14)),"")) -> 0 | R14: =IF($O14="","",IFERROR(CHOOSE(MATCH($F14,الإعدادات!$B$4:$B$7,0),INDEX('حضور سوريال'!$F$7:$F$36,$O14),INDEX('حضور غبريال'!$F$7:$F$36,$O14),INDEX('حضور رفائيل'!$F$7:$F$36,$O14),INDEX('حضور ميخائيل'!$F$7:$F$36,$O14)),"")) | S14: =IF($O14="","",IFERROR(CHOOSE(MATCH($F14,الإعدادات!$B$4:$B$7,0),INDEX('حضور سوريال'!$G$7:$G$36,$O14),INDEX('حضور غبريال'!$G$7:$G$36,$O14),INDEX('حضور رفائيل'!$G$7:$G$36,$O14),INDEX('حضور ميخائيل'!$G$7:$G$36,$O14)),"")) -> 0 | T14: =IF($O14="","",IFERROR(CHOOSE(MATCH($F14,الإعدادات!$B$4:$B$7,0),INDEX('حضور سوريال'!$H$7:$H$36,$O14),INDEX('حضور غبريال'!$H$7:$H$36,$O14),INDEX('حضور رفائيل'!$H$7:$H$36,$O14),INDEX('حضور ميخائيل'!$H$7:$H$36,$O14)),"")) -> — | U14: =IF($O14="","",IFERROR(CHOOSE(MATCH($F14,الإعدادات!$B$4:$B$7,0),INDEX('حضور سوريال'!$I$7:$I$36,$O14),INDEX('حضور غبريال'!$I$7:$I$36,$O14),INDEX('حضور رفائيل'!$I$7:$I$36,$O14),INDEX('حضور ميخائيل'!$I$7:$I$36,$O14)),"")) -> ⏳ لسه مفيش حضور | V14: =IF($O14="","",IFERROR(CHOOSE(MATCH($F14,الإعدادات!$B$4:$B$7,0),INDEX('حضور سوريال'!$BM$7:$BM$36,$O14),INDEX('حضور غبريال'!$BM$7:$BM$36,$O14),INDEX('حضور رفائيل'!$BM$7:$BM$36,$O14),INDEX('حضور ميخائيل'!$BM$7:$BM$36,$O14)),"")) -> 0 | W14: =IF(OR(V14=3,V14=4),COUNTIFS(V$6:V14,3)+COUNTIFS(V$6:V14,4),"")
A15: =IF(C15="","",ROW()-5) -> 10 | B15: =IF(C15="","","B-"&TEXT(ROW()-5,"000")) -> B-010 | C15: دانييلا توفيق شوقي | D15: ولد | E15: سنة تانية | F15: غبريال | G15: لا | H15: 01289871210 | J15: 8 شارع عبد العاطى احمد عليوة - شقة 3 الدور 3 - متفرع من شارع جوجو | M15: نشط | N15: =IF(O15="","",F15&"|"&O15) -> غبريال|10 | O15: =IF(OR(C15="",F15=""),"",COUNTIFS(F$6:F15,F15,C$6:C15,"<>")) -> 10 | P15: =IF($O15="","",IFERROR(CHOOSE(MATCH($F15,الإعدادات!$B$4:$B$7,0),INDEX('حضور سوريال'!$C$7:$C$36,$O15),INDEX('حضور غبريال'!$C$7:$C$36,$O15),INDEX('حضور رفائيل'!$C$7:$C$36,$O15),INDEX('حضور ميخائيل'!$C$7:$C$36,$O15)),"")) -> 0 | Q15: =IF($O15="","",IFERROR(CHOOSE(MATCH($F15,الإعدادات!$B$4:$B$7,0),INDEX('حضور سوريال'!$D$7:$D$36,$O15),INDEX('حضور غبريال'!$D$7:$D$36,$O15),INDEX('حضور رفائيل'!$D$7:$D$36,$O15),INDEX('حضور ميخائيل'!$D$7:$D$36,$O15)),"")) -> 0 | R15: =IF($O15="","",IFERROR(CHOOSE(MATCH($F15,الإعدادات!$B$4:$B$7,0),INDEX('حضور سوريال'!$F$7:$F$36,$O15),INDEX('حضور غبريال'!$F$7:$F$36,$O15),INDEX('حضور رفائيل'!$F$7:$F$36,$O15),INDEX('حضور ميخائيل'!$F$7:$F$36,$O15)),"")) | S15: =IF($O15="","",IFERROR(CHOOSE(MATCH($F15,الإعدادات!$B$4:$B$7,0),INDEX('حضور سوريال'!$G$7:$G$36,$O15),INDEX('حضور غبريال'!$G$7:$G$36,$O15),INDEX('حضور رفائيل'!$G$7:$G$36,$O15),INDEX('حضور ميخائيل'!$G$7:$G$36,$O15)),"")) -> 0 | T15: =IF($O15="","",IFERROR(CHOOSE(MATCH($F15,الإعدادات!$B$4:$B$7,0),INDEX('حضور سوريال'!$H$7:$H$36,$O15),INDEX('حضور غبريال'!$H$7:$H$36,$O15),INDEX('حضور رفائيل'!$H$7:$H$36,$O15),INDEX('حضور ميخائيل'!$H$7:$H$36,$O15)),"")) -> — | U15: =IF($O15="","",IFERROR(CHOOSE(MATCH($F15,الإعدادات!$B$4:$B$7,0),INDEX('حضور سوريال'!$I$7:$I$36,$O15),INDEX('حضور غبريال'!$I$7:$I$36,$O15),INDEX('حضور رفائيل'!$I$7:$I$36,$O15),INDEX('حضور ميخائيل'!$I$7:$I$36,$O15)),"")) -> ⏳ لسه مفيش حضور | V15: =IF($O15="","",IFERROR(CHOOSE(MATCH($F15,الإعدادات!$B$4:$B$7,0),INDEX('حضور سوريال'!$BM$7:$BM$36,$O15),INDEX('حضور غبريال'!$BM$7:$BM$36,$O15),INDEX('حضور رفائيل'!$BM$7:$BM$36,$O15),INDEX('حضور ميخائيل'!$BM$7:$BM$36,$O15)),"")) -> 0 | W15: =IF(OR(V15=3,V15=4),COUNTIFS(V$6:V15,3)+COUNTIFS(V$6:V15,4),"")
A16: =IF(C16="","",ROW()-5) -> 11 | B16: =IF(C16="","","B-"&TEXT(ROW()-5,"000")) -> B-011 | C16: بولا ابانوب كرم شلبى | D16: ولد | E16: سنة تانية | F16: غبريال | G16: لا | H16: 01225620289 | J16: 2 شارع محمد عبد الله سلام - شقة 6 الدور 2 - منطقة 2 | K16: #VALUE! | M16: نشط | N16: =IF(O16="","",F16&"|"&O16) -> غبريال|11 | O16: =IF(OR(C16="",F16=""),"",COUNTIFS(F$6:F16,F16,C$6:C16,"<>")) -> 11 | P16: =IF($O16="","",IFERROR(CHOOSE(MATCH($F16,الإعدادات!$B$4:$B$7,0),INDEX('حضور سوريال'!$C$7:$C$36,$O16),INDEX('حضور غبريال'!$C$7:$C$36,$O16),INDEX('حضور رفائيل'!$C$7:$C$36,$O16),INDEX('حضور ميخائيل'!$C$7:$C$36,$O16)),"")) -> 0 | Q16: =IF($O16="","",IFERROR(CHOOSE(MATCH($F16,الإعدادات!$B$4:$B$7,0),INDEX('حضور سوريال'!$D$7:$D$36,$O16),INDEX('حضور غبريال'!$D$7:$D$36,$O16),INDEX('حضور رفائيل'!$D$7:$D$36,$O16),INDEX('حضور ميخائيل'!$D$7:$D$36,$O16)),"")) -> 0 | R16: =IF($O16="","",IFERROR(CHOOSE(MATCH($F16,الإعدادات!$B$4:$B$7,0),INDEX('حضور سوريال'!$F$7:$F$36,$O16),INDEX('حضور غبريال'!$F$7:$F$36,$O16),INDEX('حضور رفائيل'!$F$7:$F$36,$O16),INDEX('حضور ميخائيل'!$F$7:$F$36,$O16)),"")) | S16: =IF($O16="","",IFERROR(CHOOSE(MATCH($F16,الإعدادات!$B$4:$B$7,0),INDEX('حضور سوريال'!$G$7:$G$36,$O16),INDEX('حضور غبريال'!$G$7:$G$36,$O16),INDEX('حضور رفائيل'!$G$7:$G$36,$O16),INDEX('حضور ميخائيل'!$G$7:$G$36,$O16)),"")) -> 0 | T16: =IF($O16="","",IFERROR(CHOOSE(MATCH($F16,الإعدادات!$B$4:$B$7,0),INDEX('حضور سوريال'!$H$7:$H$36,$O16),INDEX('حضور غبريال'!$H$7:$H$36,$O16),INDEX('حضور رفائيل'!$H$7:$H$36,$O16),INDEX('حضور ميخائيل'!$H$7:$H$36,$O16)),"")) -> — | U16: =IF($O16="","",IFERROR(CHOOSE(MATCH($F16,الإعدادات!$B$4:$B$7,0),INDEX('حضور سوريال'!$I$7:$I$36,$O16),INDEX('حضور غبريال'!$I$7:$I$36,$O16),INDEX('حضور رفائيل'!$I$7:$I$36,$O16),INDEX('حضور ميخائيل'!$I$7:$I$36,$O16)),"")) -> ⏳ لسه مفيش حضور | V16: =IF($O16="","",IFERROR(CHOOSE(MATCH($F16,الإعدادات!$B$4:$B$7,0),INDEX('حضور سوريال'!$BM$7:$BM$36,$O16),INDEX('حضور غبريال'!$BM$7:$BM$36,$O16),INDEX('حضور رفائيل'!$BM$7:$BM$36,$O16),INDEX('حضور ميخائيل'!$BM$7:$BM$36,$O16)),"")) -> 0 | W16: =IF(OR(V16=3,V16=4),COUNTIFS(V$6:V16,3)+COUNTIFS(V$6:V16,4),"")
A17: =IF(C17="","",ROW()-5) -> 12 | B17: =IF(C17="","","B-"&TEXT(ROW()-5,"000")) -> B-012 | C17: دولوريس جوزيف رزق الله | D17: بنت | E17: سنة تانية | F17: غبريال | G17: لا | H17: 01284105321 | J17: 26 شارع أحمد رفاعى - شقة 6 الدور 6 | K17: #VALUE! | M17: نشط | N17: =IF(O17="","",F17&"|"&O17) -> غبريال|12 | O17: =IF(OR(C17="",F17=""),"",COUNTIFS(F$6:F17,F17,C$6:C17,"<>")) -> 12 | P17: =IF($O17="","",IFERROR(CHOOSE(MATCH($F17,الإعدادات!$B$4:$B$7,0),INDEX('حضور سوريال'!$C$7:$C$36,$O17),INDEX('حضور غبريال'!$C$7:$C$36,$O17),INDEX('حضور رفائيل'!$C$7:$C$36,$O17),INDEX('حضور ميخائيل'!$C$7:$C$36,$O17)),"")) -> 0 | Q17: =IF($O17="","",IFERROR(CHOOSE(MATCH($F17,الإعدادات!$B$4:$B$7,0),INDEX('حضور سوريال'!$D$7:$D$36,$O17),INDEX('حضور غبريال'!$D$7:$D$36,$O17),INDEX('حضور رفائيل'!$D$7:$D$36,$O17),INDEX('حضور ميخائيل'!$D$7:$D$36,$O17)),"")) -> 0 | R17: =IF($O17="","",IFERROR(CHOOSE(MATCH($F17,الإعدادات!$B$4:$B$7,0),INDEX('حضور سوريال'!$F$7:$F$36,$O17),INDEX('حضور غبريال'!$F$7:$F$36,$O17),INDEX('حضور رفائيل'!$F$7:$F$36,$O17),INDEX('حضور ميخائيل'!$F$7:$F$36,$O17)),"")) | S17: =IF($O17="","",IFERROR(CHOOSE(MATCH($F17,الإعدادات!$B$4:$B$7,0),INDEX('حضور سوريال'!$G$7:$G$36,$O17),INDEX('حضور غبريال'!$G$7:$G$36,$O17),INDEX('حضور رفائيل'!$G$7:$G$36,$O17),INDEX('حضور ميخائيل'!$G$7:$G$36,$O17)),"")) -> 0 | T17: =IF($O17="","",IFERROR(CHOOSE(MATCH($F17,الإعدادات!$B$4:$B$7,0),INDEX('حضور سوريال'!$H$7:$H$36,$O17),INDEX('حضور غبريال'!$H$7:$H$36,$O17),INDEX('حضور رفائيل'!$H$7:$H$36,$O17),INDEX('حضور ميخائيل'!$H$7:$H$36,$O17)),"")) -> — | U17: =IF($O17="","",IFERROR(CHOOSE(MATCH($F17,الإعدادات!$B$4:$B$7,0),INDEX('حضور سوريال'!$I$7:$I$36,$O17),INDEX('حضور غبريال'!$I$7:$I$36,$O17),INDEX('حضور رفائيل'!$I$7:$I$36,$O17),INDEX('حضور ميخائيل'!$I$7:$I$36,$O17)),"")) -> ⏳ لسه مفيش حضور | V17: =IF($O17="","",IFERROR(CHOOSE(MATCH($F17,الإعدادات!$B$4:$B$7,0),INDEX('حضور سوريال'!$BM$7:$BM$36,$O17),INDEX('حضور غبريال'!$BM$7:$BM$36,$O17),INDEX('حضور رفائيل'!$BM$7:$BM$36,$O17),INDEX('حضور ميخائيل'!$BM$7:$BM$36,$O17)),"")) -> 0 | W17: =IF(OR(V17=3,V17=4),COUNTIFS(V$6:V17,3)+COUNTIFS(V$6:V17,4),"")
A18: =IF(C18="","",ROW()-5) -> 13 | B18: =IF(C18="","","B-"&TEXT(ROW()-5,"000")) -> B-013 | C18: جاستن مينا عبد السيد عطيه | D18: ولد | E18: سنة تانية | F18: غبريال | G18: لا | H18: 01205976098 | I18: 01221363758 | J18: 1 شارع على ابو عيش - شقة 1 الدور 2 - عماره المقله | K18: #VALUE! | M18: نشط | N18: =IF(O18="","",F18&"|"&O18) -> غبريال|13 | O18: =IF(OR(C18="",F18=""),"",COUNTIFS(F$6:F18,F18,C$6:C18,"<>")) -> 13 | P18: =IF($O18="","",IFERROR(CHOOSE(MATCH($F18,الإعدادات!$B$4:$B$7,0),INDEX('حضور سوريال'!$C$7:$C$36,$O18),INDEX('حضور غبريال'!$C$7:$C$36,$O18),INDEX('حضور رفائيل'!$C$7:$C$36,$O18),INDEX('حضور ميخائيل'!$C$7:$C$36,$O18)),"")) -> 0 | Q18: =IF($O18="","",IFERROR(CHOOSE(MATCH($F18,الإعدادات!$B$4:$B$7,0),INDEX('حضور سوريال'!$D$7:$D$36,$O18),INDEX('حضور غبريال'!$D$7:$D$36,$O18),INDEX('حضور رفائيل'!$D$7:$D$36,$O18),INDEX('حضور ميخائيل'!$D$7:$D$36,$O18)),"")) -> 0 | R18: =IF($O18="","",IFERROR(CHOOSE(MATCH($F18,الإعدادات!$B$4:$B$7,0),INDEX('حضور سوريال'!$F$7:$F$36,$O18),INDEX('حضور غبريال'!$F$7:$F$36,$O18),INDEX('حضور رفائيل'!$F$7:$F$36,$O18),INDEX('حضور ميخائيل'!$F$7:$F$36,$O18)),"")) | S18: =IF($O18="","",IFERROR(CHOOSE(MATCH($F18,الإعدادات!$B$4:$B$7,0),INDEX('حضور سوريال'!$G$7:$G$36,$O18),INDEX('حضور غبريال'!$G$7:$G$36,$O18),INDEX('حضور رفائيل'!$G$7:$G$36,$O18),INDEX('حضور ميخائيل'!$G$7:$G$36,$O18)),"")) -> 0 | T18: =IF($O18="","",IFERROR(CHOOSE(MATCH($F18,الإعدادات!$B$4:$B$7,0),INDEX('حضور سوريال'!$H$7:$H$36,$O18),INDEX('حضور غبريال'!$H$7:$H$36,$O18),INDEX('حضور رفائيل'!$H$7:$H$36,$O18),INDEX('حضور ميخائيل'!$H$7:$H$36,$O18)),"")) -> — | U18: =IF($O18="","",IFERROR(CHOOSE(MATCH($F18,الإعدادات!$B$4:$B$7,0),INDEX('حضور سوريال'!$I$7:$I$36,$O18),INDEX('حضور غبريال'!$I$7:$I$36,$O18),INDEX('حضور رفائيل'!$I$7:$I$36,$O18),INDEX('حضور ميخائيل'!$I$7:$I$36,$O18)),"")) -> ⏳ لسه مفيش حضور | V18: =IF($O18="","",IFERROR(CHOOSE(MATCH($F18,الإعدادات!$B$4:$B$7,0),INDEX('حضور سوريال'!$BM$7:$BM$36,$O18),INDEX('حضور غبريال'!$BM$7:$BM$36,$O18),INDEX('حضور رفائيل'!$BM$7:$BM$36,$O18),INDEX('حضور ميخائيل'!$BM$7:$BM$36,$O18)),"")) -> 0 | W18: =IF(OR(V18=3,V18=4),COUNTIFS(V$6:V18,3)+COUNTIFS(V$6:V18,4),"")
A19: =IF(C19="","",ROW()-5) -> 14 | B19: =IF(C19="","","B-"&TEXT(ROW()-5,"000")) -> B-014 | C19: جانا عبادى يوسف عبادى | D19: بنت | E19: سنة تانية | F19: غبريال | G19: لا | H19: 01273654595 | J19: 5 شارع المدارس - الارضي - الارضى | K19: #VALUE! | M19: نشط | N19: =IF(O19="","",F19&"|"&O19) -> غبريال|14 | O19: =IF(OR(C19="",F19=""),"",COUNTIFS(F$6:F19,F19,C$6:C19,"<>")) -> 14 | P19: =IF($O19="","",IFERROR(CHOOSE(MATCH($F19,الإعدادات!$B$4:$B$7,0),INDEX('حضور سوريال'!$C$7:$C$36,$O19),INDEX('حضور غبريال'!$C$7:$C$36,$O19),INDEX('حضور رفائيل'!$C$7:$C$36,$O19),INDEX('حضور ميخائيل'!$C$7:$C$36,$O19)),"")) -> 0 | Q19: =IF($O19="","",IFERROR(CHOOSE(MATCH($F19,الإعدادات!$B$4:$B$7,0),INDEX('حضور سوريال'!$D$7:$D$36,$O19),INDEX('حضور غبريال'!$D$7:$D$36,$O19),INDEX('حضور رفائيل'!$D$7:$D$36,$O19),INDEX('حضور ميخائيل'!$D$7:$D$36,$O19)),"")) -> 0 | R19: =IF($O19="","",IFERROR(CHOOSE(MATCH($F19,الإعدادات!$B$4:$B$7,0),INDEX('حضور سوريال'!$F$7:$F$36,$O19),INDEX('حضور غبريال'!$F$7:$F$36,$O19),INDEX('حضور رفائيل'!$F$7:$F$36,$O19),INDEX('حضور ميخائيل'!$F$7:$F$36,$O19)),"")) | S19: =IF($O19="","",IFERROR(CHOOSE(MATCH($F19,الإعدادات!$B$4:$B$7,0),INDEX('حضور سوريال'!$G$7:$G$36,$O19),INDEX('حضور غبريال'!$G$7:$G$36,$O19),INDEX('حضور رفائيل'!$G$7:$G$36,$O19),INDEX('حضور ميخائيل'!$G$7:$G$36,$O19)),"")) -> 0 | T19: =IF($O19="","",IFERROR(CHOOSE(MATCH($F19,الإعدادات!$B$4:$B$7,0),INDEX('حضور سوريال'!$H$7:$H$36,$O19),INDEX('حضور غبريال'!$H$7:$H$36,$O19),INDEX('حضور رفائيل'!$H$7:$H$36,$O19),INDEX('حضور ميخائيل'!$H$7:$H$36,$O19)),"")) -> — | U19: =IF($O19="","",IFERROR(CHOOSE(MATCH($F19,الإعدادات!$B$4:$B$7,0),INDEX('حضور سوريال'!$I$7:$I$36,$O19),INDEX('حضور غبريال'!$I$7:$I$36,$O19),INDEX('حضور رفائيل'!$I$7:$I$36,$O19),INDEX('حضور ميخائيل'!$I$7:$I$36,$O19)),"")) -> ⏳ لسه مفيش حضور | V19: =IF($O19="","",IFERROR(CHOOSE(MATCH($F19,الإعدادات!$B$4:$B$7,0),INDEX('حضور سوريال'!$BM$7:$BM$36,$O19),INDEX('حضور غبريال'!$BM$7:$BM$36,$O19),INDEX('حضور رفائيل'!$BM$7:$BM$36,$O19),INDEX('حضور ميخائيل'!$BM$7:$BM$36,$O19)),"")) -> 0 | W19: =IF(OR(V19=3,V19=4),COUNTIFS(V$6:V19,3)+COUNTIFS(V$6:V19,4),"")
A20: =IF(C20="","",ROW()-5) -> 15 | B20: =IF(C20="","","B-"&TEXT(ROW()-5,"000")) -> B-015 | C20: يوسف ميلاد رسمى بقطر | D20: ولد | E20: سنة تانية | F20: غبريال | G20: لا | H20: 01210019391 | I20: 01277561044 | J20: 2 شارع فايز مترى - شقة 5 الدور 3 - يمين / مجدى البقال | M20: نشط | N20: =IF(O20="","",F20&"|"&O20) -> غبريال|15 | O20: =IF(OR(C20="",F20=""),"",COUNTIFS(F$6:F20,F20,C$6:C20,"<>")) -> 15 | P20: =IF($O20="","",IFERROR(CHOOSE(MATCH($F20,الإعدادات!$B$4:$B$7,0),INDEX('حضور سوريال'!$C$7:$C$36,$O20),INDEX('حضور غبريال'!$C$7:$C$36,$O20),INDEX('حضور رفائيل'!$C$7:$C$36,$O20),INDEX('حضور ميخائيل'!$C$7:$C$36,$O20)),"")) -> 0 | Q20: =IF($O20="","",IFERROR(CHOOSE(MATCH($F20,الإعدادات!$B$4:$B$7,0),INDEX('حضور سوريال'!$D$7:$D$36,$O20),INDEX('حضور غبريال'!$D$7:$D$36,$O20),INDEX('حضور رفائيل'!$D$7:$D$36,$O20),INDEX('حضور ميخائيل'!$D$7:$D$36,$O20)),"")) -> 0 | R20: =IF($O20="","",IFERROR(CHOOSE(MATCH($F20,الإعدادات!$B$4:$B$7,0),INDEX('حضور سوريال'!$F$7:$F$36,$O20),INDEX('حضور غبريال'!$F$7:$F$36,$O20),INDEX('حضور رفائيل'!$F$7:$F$36,$O20),INDEX('حضور ميخائيل'!$F$7:$F$36,$O20)),"")) | S20: =IF($O20="","",IFERROR(CHOOSE(MATCH($F20,الإعدادات!$B$4:$B$7,0),INDEX('حضور سوريال'!$G$7:$G$36,$O20),INDEX('حضور غبريال'!$G$7:$G$36,$O20),INDEX('حضور رفائيل'!$G$7:$G$36,$O20),INDEX('حضور ميخائيل'!$G$7:$G$36,$O20)),"")) -> 0 | T20: =IF($O20="","",IFERROR(CHOOSE(MATCH($F20,الإعدادات!$B$4:$B$7,0),INDEX('حضور سوريال'!$H$7:$H$36,$O20),INDEX('حضور غبريال'!$H$7:$H$36,$O20),INDEX('حضور رفائيل'!$H$7:$H$36,$O20),INDEX('حضور ميخائيل'!$H$7:$H$36,$O20)),"")) -> — | U20: =IF($O20="","",IFERROR(CHOOSE(MATCH($F20,الإعدادات!$B$4:$B$7,0),INDEX('حضور سوريال'!$I$7:$I$36,$O20),INDEX('حضور غبريال'!$I$7:$I$36,$O20),INDEX('حضور رفائيل'!$I$7:$I$36,$O20),INDEX('حضور ميخائيل'!$I$7:$I$36,$O20)),"")) -> ⏳ لسه مفيش حضور | V20: =IF($O20="","",IFERROR(CHOOSE(MATCH($F20,الإعدادات!$B$4:$B$7,0),INDEX('حضور سوريال'!$BM$7:$BM$36,$O20),INDEX('حضور غبريال'!$BM$7:$BM$36,$O20),INDEX('حضور رفائيل'!$BM$7:$BM$36,$O20),INDEX('حضور ميخائيل'!$BM$7:$BM$36,$O20)),"")) -> 0 | W20: =IF(OR(V20=3,V20=4),COUNTIFS(V$6:V20,3)+COUNTIFS(V$6:V20,4),"")
A21: =IF(C21="","",ROW()-5) -> 16 | B21: =IF(C21="","","B-"&TEXT(ROW()-5,"000")) -> B-016 | C21: ايرينى ريمون حنا | D21: بنت | E21: سنة تانية | F21: غبريال | G21: لا | H21: 01221026225 | J21: 24 شارع مرزق مرزوق الدور 2 | M21: نشط | N21: =IF(O21="","",F21&"|"&O21) -> غبريال|16 | O21: =IF(OR(C21="",F21=""),"",COUNTIFS(F$6:F21,F21,C$6:C21,"<>")) -> 16 | P21: =IF($O21="","",IFERROR(CHOOSE(MATCH($F21,الإعدادات!$B$4:$B$7,0),INDEX('حضور سوريال'!$C$7:$C$36,$O21),INDEX('حضور غبريال'!$C$7:$C$36,$O21),INDEX('حضور رفائيل'!$C$7:$C$36,$O21),INDEX('حضور ميخائيل'!$C$7:$C$36,$O21)),"")) -> 0 | Q21: =IF($O21="","",IFERROR(CHOOSE(MATCH($F21,الإعدادات!$B$4:$B$7,0),INDEX('حضور سوريال'!$D$7:$D$36,$O21),INDEX('حضور غبريال'!$D$7:$D$36,$O21),INDEX('حضور رفائيل'!$D$7:$D$36,$O21),INDEX('حضور ميخائيل'!$D$7:$D$36,$O21)),"")) -> 0 | R21: =IF($O21="","",IFERROR(CHOOSE(MATCH($F21,الإعدادات!$B$4:$B$7,0),INDEX('حضور سوريال'!$F$7:$F$36,$O21),INDEX('حضور غبريال'!$F$7:$F$36,$O21),INDEX('حضور رفائيل'!$F$7:$F$36,$O21),INDEX('حضور ميخائيل'!$F$7:$F$36,$O21)),"")) | S21: =IF($O21="","",IFERROR(CHOOSE(MATCH($F21,الإعدادات!$B$4:$B$7,0),INDEX('حضور سوريال'!$G$7:$G$36,$O21),INDEX('حضور غبريال'!$G$7:$G$36,$O21),INDEX('حضور رفائيل'!$G$7:$G$36,$O21),INDEX('حضور ميخائيل'!$G$7:$G$36,$O21)),"")) -> 0 | T21: =IF($O21="","",IFERROR(CHOOSE(MATCH($F21,الإعدادات!$B$4:$B$7,0),INDEX('حضور سوريال'!$H$7:$H$36,$O21),INDEX('حضور غبريال'!$H$7:$H$36,$O21),INDEX('حضور رفائيل'!$H$7:$H$36,$O21),INDEX('حضور ميخائيل'!$H$7:$H$36,$O21)),"")) -> — | U21: =IF($O21="","",IFERROR(CHOOSE(MATCH($F21,الإعدادات!$B$4:$B$7,0),INDEX('حضور سوريال'!$I$7:$I$36,$O21),INDEX('حضور غبريال'!$I$7:$I$36,$O21),INDEX('حضور رفائيل'!$I$7:$I$36,$O21),INDEX('حضور ميخائيل'!$I$7:$I$36,$O21)),"")) -> ⏳ لسه مفيش حضور | V21: =IF($O21="","",IFERROR(CHOOSE(MATCH($F21,الإعدادات!$B$4:$B$7,0),INDEX('حضور سوريال'!$BM$7:$BM$36,$O21),INDEX('حضور غبريال'!$BM$7:$BM$36,$O21),INDEX('حضور رفائيل'!$BM$7:$BM$36,$O21),INDEX('حضور ميخائيل'!$BM$7:$BM$36,$O21)),"")) -> 0 | W21: =IF(OR(V21=3,V21=4),COUNTIFS(V$6:V21,3)+COUNTIFS(V$6:V21,4),"")
A22: =IF(C22="","",ROW()-5) -> 17 | B22: =IF(C22="","","B-"&TEXT(ROW()-5,"000")) -> B-017 | C22: يوستينا سامي عريان سامى فرج | D22: بنت | E22: سنة تانية | F22: غبريال | G22: لا | H22: 01270302120 | J22: 10 شارع عطية عبد اللطيف - شقة 2 الدور 2 | M22: نشط | N22: =IF(O22="","",F22&"|"&O22) -> غبريال|17 | O22: =IF(OR(C22="",F22=""),"",COUNTIFS(F$6:F22,F22,C$6:C22,"<>")) -> 17 | P22: =IF($O22="","",IFERROR(CHOOSE(MATCH($F22,الإعدادات!$B$4:$B$7,0),INDEX('حضور سوريال'!$C$7:$C$36,$O22),INDEX('حضور غبريال'!$C$7:$C$36,$O22),INDEX('حضور رفائيل'!$C$7:$C$36,$O22),INDEX('حضور ميخائيل'!$C$7:$C$36,$O22)),"")) -> 0 | Q22: =IF($O22="","",IFERROR(CHOOSE(MATCH($F22,الإعدادات!$B$4:$B$7,0),INDEX('حضور سوريال'!$D$7:$D$36,$O22),INDEX('حضور غبريال'!$D$7:$D$36,$O22),INDEX('حضور رفائيل'!$D$7:$D$36,$O22),INDEX('حضور ميخائيل'!$D$7:$D$36,$O22)),"")) -> 0 | R22: =IF($O22="","",IFERROR(CHOOSE(MATCH($F22,الإعدادات!$B$4:$B$7,0),INDEX('حضور سوريال'!$F$7:$F$36,$O22),INDEX('حضور غبريال'!$F$7:$F$36,$O22),INDEX('حضور رفائيل'!$F$7:$F$36,$O22),INDEX('حضور ميخائيل'!$F$7:$F$36,$O22)),"")) | S22: =IF($O22="","",IFERROR(CHOOSE(MATCH($F22,الإعدادات!$B$4:$B$7,0),INDEX('حضور سوريال'!$G$7:$G$36,$O22),INDEX('حضور غبريال'!$G$7:$G$36,$O22),INDEX('حضور رفائيل'!$G$7:$G$36,$O22),INDEX('حضور ميخائيل'!$G$7:$G$36,$O22)),"")) -> 0 | T22: =IF($O22="","",IFERROR(CHOOSE(MATCH($F22,الإعدادات!$B$4:$B$7,0),INDEX('حضور سوريال'!$H$7:$H$36,$O22),INDEX('حضور غبريال'!$H$7:$H$36,$O22),INDEX('حضور رفائيل'!$H$7:$H$36,$O22),INDEX('حضور ميخائيل'!$H$7:$H$36,$O22)),"")) -> — | U22: =IF($O22="","",IFERROR(CHOOSE(MATCH($F22,الإعدادات!$B$4:$B$7,0),INDEX('حضور سوريال'!$I$7:$I$36,$O22),INDEX('حضور غبريال'!$I$7:$I$36,$O22),INDEX('حضور رفائيل'!$I$7:$I$36,$O22),INDEX('حضور ميخائيل'!$I$7:$I$36,$O22)),"")) -> ⏳ لسه مفيش حضور | V22: =IF($O22="","",IFERROR(CHOOSE(MATCH($F22,الإعدادات!$B$4:$B$7,0),INDEX('حضور سوريال'!$BM$7:$BM$36,$O22),INDEX('حضور غبريال'!$BM$7:$BM$36,$O22),INDEX('حضور رفائيل'!$BM$7:$BM$36,$O22),INDEX('حضور ميخائيل'!$BM$7:$BM$36,$O22)),"")) -> 0 | W22: =IF(OR(V22=3,V22=4),COUNTIFS(V$6:V22,3)+COUNTIFS(V$6:V22,4),"")
A23: =IF(C23="","",ROW()-5) -> 18 | B23: =IF(C23="","","B-"&TEXT(ROW()-5,"000")) -> B-018 | C23: مارتينوس مايكل ميشيل | D23: ولد | E23: سنة تانية | F23: غبريال | G23: لا | H23: 01224857003 | J23: 13 شارع منطقة أ - شقة 1 الدور 1 | M23: نشط | N23: =IF(O23="","",F23&"|"&O23) -> غبريال|18 | O23: =IF(OR(C23="",F23=""),"",COUNTIFS(F$6:F23,F23,C$6:C23,"<>")) -> 18 | P23: =IF($O23="","",IFERROR(CHOOSE(MATCH($F23,الإعدادات!$B$4:$B$7,0),INDEX('حضور سوريال'!$C$7:$C$36,$O23),INDEX('حضور غبريال'!$C$7:$C$36,$O23),INDEX('حضور رفائيل'!$C$7:$C$36,$O23),INDEX('حضور ميخائيل'!$C$7:$C$36,$O23)),"")) -> 0 | Q23: =IF($O23="","",IFERROR(CHOOSE(MATCH($F23,الإعدادات!$B$4:$B$7,0),INDEX('حضور سوريال'!$D$7:$D$36,$O23),INDEX('حضور غبريال'!$D$7:$D$36,$O23),INDEX('حضور رفائيل'!$D$7:$D$36,$O23),INDEX('حضور ميخائيل'!$D$7:$D$36,$O23)),"")) -> 0 | R23: =IF($O23="","",IFERROR(CHOOSE(MATCH($F23,الإعدادات!$B$4:$B$7,0),INDEX('حضور سوريال'!$F$7:$F$36,$O23),INDEX('حضور غبريال'!$F$7:$F$36,$O23),INDEX('حضور رفائيل'!$F$7:$F$36,$O23),INDEX('حضور ميخائيل'!$F$7:$F$36,$O23)),"")) | S23: =IF($O23="","",IFERROR(CHOOSE(MATCH($F23,الإعدادات!$B$4:$B$7,0),INDEX('حضور سوريال'!$G$7:$G$36,$O23),INDEX('حضور غبريال'!$G$7:$G$36,$O23),INDEX('حضور رفائيل'!$G$7:$G$36,$O23),INDEX('حضور ميخائيل'!$G$7:$G$36,$O23)),"")) -> 0 | T23: =IF($O23="","",IFERROR(CHOOSE(MATCH($F23,الإعدادات!$B$4:$B$7,0),INDEX('حضور سوريال'!$H$7:$H$36,$O23),INDEX('حضور غبريال'!$H$7:$H$36,$O23),INDEX('حضور رفائيل'!$H$7:$H$36,$O23),INDEX('حضور ميخائيل'!$H$7:$H$36,$O23)),"")) -> — | U23: =IF($O23="","",IFERROR(CHOOSE(MATCH($F23,الإعدادات!$B$4:$B$7,0),INDEX('حضور سوريال'!$I$7:$I$36,$O23),INDEX('حضور غبريال'!$I$7:$I$36,$O23),INDEX('حضور رفائيل'!$I$7:$I$36,$O23),INDEX('حضور ميخائيل'!$I$7:$I$36,$O23)),"")) -> ⏳ لسه مفيش حضور | V23: =IF($O23="","",IFERROR(CHOOSE(MATCH($F23,الإعدادات!$B$4:$B$7,0),INDEX('حضور سوريال'!$BM$7:$BM$36,$O23),INDEX('حضور غبريال'!$BM$7:$BM$36,$O23),INDEX('حضور رفائيل'!$BM$7:$BM$36,$O23),INDEX('حضور ميخائيل'!$BM$7:$BM$36,$O23)),"")) -> 0 | W23: =IF(OR(V23=3,V23=4),COUNTIFS(V$6:V23,3)+COUNTIFS(V$6:V23,4),"")
A24: =IF(C24="","",ROW()-5) -> 19 | B24: =IF(C24="","","B-"&TEXT(ROW()-5,"000")) -> B-019 | C24: جونير بسام نصرى مكرم | D24: بنت | E24: سنة تانية | F24: غبريال | G24: لا | H24: 01273998657 | J24: 843 شارع بورسعيد - شقة 4 الدور 2 - مدخل الشونة | K24: #VALUE! | M24: نشط | N24: =IF(O24="","",F24&"|"&O24) -> غبريال|19 | O24: =IF(OR(C24="",F24=""),"",COUNTIFS(F$6:F24,F24,C$6:C24,"<>")) -> 19 | P24: =IF($O24="","",IFERROR(CHOOSE(MATCH($F24,الإعدادات!$B$4:$B$7,0),INDEX('حضور سوريال'!$C$7:$C$36,$O24),INDEX('حضور غبريال'!$C$7:$C$36,$O24),INDEX('حضور رفائيل'!$C$7:$C$36,$O24),INDEX('حضور ميخائيل'!$C$7:$C$36,$O24)),"")) -> 0 | Q24: =IF($O24="","",IFERROR(CHOOSE(MATCH($F24,الإعدادات!$B$4:$B$7,0),INDEX('حضور سوريال'!$D$7:$D$36,$O24),INDEX('حضور غبريال'!$D$7:$D$36,$O24),INDEX('حضور رفائيل'!$D$7:$D$36,$O24),INDEX('حضور ميخائيل'!$D$7:$D$36,$O24)),"")) -> 0 | R24: =IF($O24="","",IFERROR(CHOOSE(MATCH($F24,الإعدادات!$B$4:$B$7,0),INDEX('حضور سوريال'!$F$7:$F$36,$O24),INDEX('حضور غبريال'!$F$7:$F$36,$O24),INDEX('حضور رفائيل'!$F$7:$F$36,$O24),INDEX('حضور ميخائيل'!$F$7:$F$36,$O24)),"")) | S24: =IF($O24="","",IFERROR(CHOOSE(MATCH($F24,الإعدادات!$B$4:$B$7,0),INDEX('حضور سوريال'!$G$7:$G$36,$O24),INDEX('حضور غبريال'!$G$7:$G$36,$O24),INDEX('حضور رفائيل'!$G$7:$G$36,$O24),INDEX('حضور ميخائيل'!$G$7:$G$36,$O24)),"")) -> 0 | T24: =IF($O24="","",IFERROR(CHOOSE(MATCH($F24,الإعدادات!$B$4:$B$7,0),INDEX('حضور سوريال'!$H$7:$H$36,$O24),INDEX('حضور غبريال'!$H$7:$H$36,$O24),INDEX('حضور رفائيل'!$H$7:$H$36,$O24),INDEX('حضور ميخائيل'!$H$7:$H$36,$O24)),"")) -> — | U24: =IF($O24="","",IFERROR(CHOOSE(MATCH($F24,الإعدادات!$B$4:$B$7,0),INDEX('حضور سوريال'!$I$7:$I$36,$O24),INDEX('حضور غبريال'!$I$7:$I$36,$O24),INDEX('حضور رفائيل'!$I$7:$I$36,$O24),INDEX('حضور ميخائيل'!$I$7:$I$36,$O24)),"")) -> ⏳ لسه مفيش حضور | V24: =IF($O24="","",IFERROR(CHOOSE(MATCH($F24,الإعدادات!$B$4:$B$7,0),INDEX('حضور سوريال'!$BM$7:$BM$36,$O24),INDEX('حضور غبريال'!$BM$7:$BM$36,$O24),INDEX('حضور رفائيل'!$BM$7:$BM$36,$O24),INDEX('حضور ميخائيل'!$BM$7:$BM$36,$O24)),"")) -> 0 | W24: =IF(OR(V24=3,V24=4),COUNTIFS(V$6:V24,3)+COUNTIFS(V$6:V24,4),"")
A25: =IF(C25="","",ROW()-5) -> 20 | B25: =IF(C25="","","B-"&TEXT(ROW()-5,"000")) -> B-020 | C25: مريم عماد زارع | D25: بنت | E25: سنة تانية | F25: غبريال | G25: لا | H25: 01206191722 | J25: 44 شارع ترعة حمزة - شقة 1 الدور 3 - فوق صيدليه عماد بعد الارضى الشقة شمال السلم | K25: #VALUE! | M25: نشط | N25: =IF(O25="","",F25&"|"&O25) -> غبريال|20 | O25: =IF(OR(C25="",F25=""),"",COUNTIFS(F$6:F25,F25,C$6:C25,"<>")) -> 20 | P25: =IF($O25="","",IFERROR(CHOOSE(MATCH($F25,الإعدادات!$B$4:$B$7,0),INDEX('حضور سوريال'!$C$7:$C$36,$O25),INDEX('حضور غبريال'!$C$7:$C$36,$O25),INDEX('حضور رفائيل'!$C$7:$C$36,$O25),INDEX('حضور ميخائيل'!$C$7:$C$36,$O25)),"")) -> 0 | Q25: =IF($O25="","",IFERROR(CHOOSE(MATCH($F25,الإعدادات!$B$4:$B$7,0),INDEX('حضور سوريال'!$D$7:$D$36,$O25),INDEX('حضور غبريال'!$D$7:$D$36,$O25),INDEX('حضور رفائيل'!$D$7:$D$36,$O25),INDEX('حضور ميخائيل'!$D$7:$D$36,$O25)),"")) -> 0 | R25: =IF($O25="","",IFERROR(CHOOSE(MATCH($F25,الإعدادات!$B$4:$B$7,0),INDEX('حضور سوريال'!$F$7:$F$36,$O25),INDEX('حضور غبريال'!$F$7:$F$36,$O25),INDEX('حضور رفائيل'!$F$7:$F$36,$O25),INDEX('حضور ميخائيل'!$F$7:$F$36,$O25)),"")) | S25: =IF($O25="","",IFERROR(CHOOSE(MATCH($F25,الإعدادات!$B$4:$B$7,0),INDEX('حضور سوريال'!$G$7:$G$36,$O25),INDEX('حضور غبريال'!$G$7:$G$36,$O25),INDEX('حضور رفائيل'!$G$7:$G$36,$O25),INDEX('حضور ميخائيل'!$G$7:$G$36,$O25)),"")) -> 0 | T25: =IF($O25="","",IFERROR(CHOOSE(MATCH($F25,الإعدادات!$B$4:$B$7,0),INDEX('حضور سوريال'!$H$7:$H$36,$O25),INDEX('حضور غبريال'!$H$7:$H$36,$O25),INDEX('حضور رفائيل'!$H$7:$H$36,$O25),INDEX('حضور ميخائيل'!$H$7:$H$36,$O25)),"")) -> — | U25: =IF($O25="","",IFERROR(CHOOSE(MATCH($F25,الإعدادات!$B$4:$B$7,0),INDEX('حضور سوريال'!$I$7:$I$36,$O25),INDEX('حضور غبريال'!$I$7:$I$36,$O25),INDEX('حضور رفائيل'!$I$7:$I$36,$O25),INDEX('حضور ميخائيل'!$I$7:$I$36,$O25)),"")) -> ⏳ لسه مفيش حضور | V25: =IF($O25="","",IFERROR(CHOOSE(MATCH($F25,الإعدادات!$B$4:$B$7,0),INDEX('حضور سوريال'!$BM$7:$BM$36,$O25),INDEX('حضور غبريال'!$BM$7:$BM$36,$O25),INDEX('حضور رفائيل'!$BM$7:$BM$36,$O25),INDEX('حضور ميخائيل'!$BM$7:$BM$36,$O25)),"")) -> 0 | W25: =IF(OR(V25=3,V25=4),COUNTIFS(V$6:V25,3)+COUNTIFS(V$6:V25,4),"")
A26: =IF(C26="","",ROW()-5) -> 21 | B26: =IF(C26="","","B-"&TEXT(ROW()-5,"000")) -> B-021 | C26: ماروسكا ميشيل ثروت | D26: بنت | E26: سنة تانية | F26: غبريال | G26: لا | H26: 01206111792 | J26: 4 شارع خاتم المرسلين - الدور 5 | K26: #VALUE! | M26: نشط | N26: =IF(O26="","",F26&"|"&O26) -> غبريال|21 | O26: =IF(OR(C26="",F26=""),"",COUNTIFS(F$6:F26,F26,C$6:C26,"<>")) -> 21 | P26: =IF($O26="","",IFERROR(CHOOSE(MATCH($F26,الإعدادات!$B$4:$B$7,0),INDEX('حضور سوريال'!$C$7:$C$36,$O26),INDEX('حضور غبريال'!$C$7:$C$36,$O26),INDEX('حضور رفائيل'!$C$7:$C$36,$O26),INDEX('حضور ميخائيل'!$C$7:$C$36,$O26)),"")) -> 0 | Q26: =IF($O26="","",IFERROR(CHOOSE(MATCH($F26,الإعدادات!$B$4:$B$7,0),INDEX('حضور سوريال'!$D$7:$D$36,$O26),INDEX('حضور غبريال'!$D$7:$D$36,$O26),INDEX('حضور رفائيل'!$D$7:$D$36,$O26),INDEX('حضور ميخائيل'!$D$7:$D$36,$O26)),"")) -> 0 | R26: =IF($O26="","",IFERROR(CHOOSE(MATCH($F26,الإعدادات!$B$4:$B$7,0),INDEX('حضور سوريال'!$F$7:$F$36,$O26),INDEX('حضور غبريال'!$F$7:$F$36,$O26),INDEX('حضور رفائيل'!$F$7:$F$36,$O26),INDEX('حضور ميخائيل'!$F$7:$F$36,$O26)),"")) | S26: =IF($O26="","",IFERROR(CHOOSE(MATCH($F26,الإعدادات!$B$4:$B$7,0),INDEX('حضور سوريال'!$G$7:$G$36,$O26),INDEX('حضور غبريال'!$G$7:$G$36,$O26),INDEX('حضور رفائيل'!$G$7:$G$36,$O26),INDEX('حضور ميخائيل'!$G$7:$G$36,$O26)),"")) -> 0 | T26: =IF($O26="","",IFERROR(CHOOSE(MATCH($F26,الإعدادات!$B$4:$B$7,0),INDEX('حضور سوريال'!$H$7:$H$36,$O26),INDEX('حضور غبريال'!$H$7:$H$36,$O26),INDEX('حضور رفائيل'!$H$7:$H$36,$O26),INDEX('حضور ميخائيل'!$H$7:$H$36,$O26)),"")) -> — | U26: =IF($O26="","",IFERROR(CHOOSE(MATCH($F26,الإعدادات!$B$4:$B$7,0),INDEX('حضور سوريال'!$I$7:$I$36,$O26),INDEX('حضور غبريال'!$I$7:$I$36,$O26),INDEX('حضور رفائيل'!$I$7:$I$36,$O26),INDEX('حضور ميخائيل'!$I$7:$I$36,$O26)),"")) -> ⏳ لسه مفيش حضور | V26: =IF($O26="","",IFERROR(CHOOSE(MATCH($F26,الإعدادات!$B$4:$B$7,0),INDEX('حضور سوريال'!$BM$7:$BM$36,$O26),INDEX('حضور غبريال'!$BM$7:$BM$36,$O26),INDEX('حضور رفائيل'!$BM$7:$BM$36,$O26),INDEX('حضور ميخائيل'!$BM$7:$BM$36,$O26)),"")) -> 0 | W26: =IF(OR(V26=3,V26=4),COUNTIFS(V$6:V26,3)+COUNTIFS(V$6:V26,4),"")
A27: =IF(C27="","",ROW()-5) -> 22 | B27: =IF(C27="","","B-"&TEXT(ROW()-5,"000")) -> B-022 | C27: بيرلا مايكل خليل | D27: بنت | E27: سنة تانية | F27: غبريال | G27: لا | H27: 01210949273 | J27: 3 شارع عمرو عبد العزيز - شقة 1 الدور 1 | K27: #VALUE! | M27: نشط | N27: =IF(O27="","",F27&"|"&O27) -> غبريال|22 | O27: =IF(OR(C27="",F27=""),"",COUNTIFS(F$6:F27,F27,C$6:C27,"<>")) -> 22 | P27: =IF($O27="","",IFERROR(CHOOSE(MATCH($F27,الإعدادات!$B$4:$B$7,0),INDEX('حضور سوريال'!$C$7:$C$36,$O27),INDEX('حضور غبريال'!$C$7:$C$36,$O27),INDEX('حضور رفائيل'!$C$7:$C$36,$O27),INDEX('حضور ميخائيل'!$C$7:$C$36,$O27)),"")) -> 0 | Q27: =IF($O27="","",IFERROR(CHOOSE(MATCH($F27,الإعدادات!$B$4:$B$7,0),INDEX('حضور سوريال'!$D$7:$D$36,$O27),INDEX('حضور غبريال'!$D$7:$D$36,$O27),INDEX('حضور رفائيل'!$D$7:$D$36,$O27),INDEX('حضور ميخائيل'!$D$7:$D$36,$O27)),"")) -> 0 | R27: =IF($O27="","",IFERROR(CHOOSE(MATCH($F27,الإعدادات!$B$4:$B$7,0),INDEX('حضور سوريال'!$F$7:$F$36,$O27),INDEX('حضور غبريال'!$F$7:$F$36,$O27),INDEX('حضور رفائيل'!$F$7:$F$36,$O27),INDEX('حضور ميخائيل'!$F$7:$F$36,$O27)),"")) | S27: =IF($O27="","",IFERROR(CHOOSE(MATCH($F27,الإعدادات!$B$4:$B$7,0),INDEX('حضور سوريال'!$G$7:$G$36,$O27),INDEX('حضور غبريال'!$G$7:$G$36,$O27),INDEX('حضور رفائيل'!$G$7:$G$36,$O27),INDEX('حضور ميخائيل'!$G$7:$G$36,$O27)),"")) -> 0 | T27: =IF($O27="","",IFERROR(CHOOSE(MATCH($F27,الإعدادات!$B$4:$B$7,0),INDEX('حضور سوريال'!$H$7:$H$36,$O27),INDEX('حضور غبريال'!$H$7:$H$36,$O27),INDEX('حضور رفائيل'!$H$7:$H$36,$O27),INDEX('حضور ميخائيل'!$H$7:$H$36,$O27)),"")) -> — | U27: =IF($O27="","",IFERROR(CHOOSE(MATCH($F27,الإعدادات!$B$4:$B$7,0),INDEX('حضور سوريال'!$I$7:$I$36,$O27),INDEX('حضور غبريال'!$I$7:$I$36,$O27),INDEX('حضور رفائيل'!$I$7:$I$36,$O27),INDEX('حضور ميخائيل'!$I$7:$I$36,$O27)),"")) -> ⏳ لسه مفيش حضور | V27: =IF($O27="","",IFERROR(CHOOSE(MATCH($F27,الإعدادات!$B$4:$B$7,0),INDEX('حضور سوريال'!$BM$7:$BM$36,$O27),INDEX('حضور غبريال'!$BM$7:$BM$36,$O27),INDEX('حضور رفائيل'!$BM$7:$BM$36,$O27),INDEX('حضور ميخائيل'!$BM$7:$BM$36,$O27)),"")) -> 0 | W27: =IF(OR(V27=3,V27=4),COUNTIFS(V$6:V27,3)+COUNTIFS(V$6:V27,4),"")
A28: =IF(C28="","",ROW()-5) -> 23 | B28: =IF(C28="","","B-"&TEXT(ROW()-5,"000")) -> B-023 | C28: مورين مينا عوض | D28: بنت | E28: سنة تانية | F28: غبريال | G28: لا | H28: 01227989278 | J28: 23 شارع أحمد رفاعى - شقة 1 - الارضى - مورين و انجى مع عائلة الجد مكرم حبيب بقطر فى نفس الشقة | M28: نشط | N28: =IF(O28="","",F28&"|"&O28) -> غبريال|23 | O28: =IF(OR(C28="",F28=""),"",COUNTIFS(F$6:F28,F28,C$6:C28,"<>")) -> 23 | P28: =IF($O28="","",IFERROR(CHOOSE(MATCH($F28,الإعدادات!$B$4:$B$7,0),INDEX('حضور سوريال'!$C$7:$C$36,$O28),INDEX('حضور غبريال'!$C$7:$C$36,$O28),INDEX('حضور رفائيل'!$C$7:$C$36,$O28),INDEX('حضور ميخائيل'!$C$7:$C$36,$O28)),"")) -> 0 | Q28: =IF($O28="","",IFERROR(CHOOSE(MATCH($F28,الإعدادات!$B$4:$B$7,0),INDEX('حضور سوريال'!$D$7:$D$36,$O28),INDEX('حضور غبريال'!$D$7:$D$36,$O28),INDEX('حضور رفائيل'!$D$7:$D$36,$O28),INDEX('حضور ميخائيل'!$D$7:$D$36,$O28)),"")) -> 0 | R28: =IF($O28="","",IFERROR(CHOOSE(MATCH($F28,الإعدادات!$B$4:$B$7,0),INDEX('حضور سوريال'!$F$7:$F$36,$O28),INDEX('حضور غبريال'!$F$7:$F$36,$O28),INDEX('حضور رفائيل'!$F$7:$F$36,$O28),INDEX('حضور ميخائيل'!$F$7:$F$36,$O28)),"")) | S28: =IF($O28="","",IFERROR(CHOOSE(MATCH($F28,الإعدادات!$B$4:$B$7,0),INDEX('حضور سوريال'!$G$7:$G$36,$O28),INDEX('حضور غبريال'!$G$7:$G$36,$O28),INDEX('حضور رفائيل'!$G$7:$G$36,$O28),INDEX('حضور ميخائيل'!$G$7:$G$36,$O28)),"")) -> 0 | T28: =IF($O28="","",IFERROR(CHOOSE(MATCH($F28,الإعدادات!$B$4:$B$7,0),INDEX('حضور سوريال'!$H$7:$H$36,$O28),INDEX('حضور غبريال'!$H$7:$H$36,$O28),INDEX('حضور رفائيل'!$H$7:$H$36,$O28),INDEX('حضور ميخائيل'!$H$7:$H$36,$O28)),"")) -> — | U28: =IF($O28="","",IFERROR(CHOOSE(MATCH($F28,الإعدادات!$B$4:$B$7,0),INDEX('حضور سوريال'!$I$7:$I$36,$O28),INDEX('حضور غبريال'!$I$7:$I$36,$O28),INDEX('حضور رفائيل'!$I$7:$I$36,$O28),INDEX('حضور ميخائيل'!$I$7:$I$36,$O28)),"")) -> ⏳ لسه مفيش حضور | V28: =IF($O28="","",IFERROR(CHOOSE(MATCH($F28,الإعدادات!$B$4:$B$7,0),INDEX('حضور سوريال'!$BM$7:$BM$36,$O28),INDEX('حضور غبريال'!$BM$7:$BM$36,$O28),INDEX('حضور رفائيل'!$BM$7:$BM$36,$O28),INDEX('حضور ميخائيل'!$BM$7:$BM$36,$O28)),"")) -> 0 | W28: =IF(OR(V28=3,V28=4),COUNTIFS(V$6:V28,3)+COUNTIFS(V$6:V28,4),"")
A29: =IF(C29="","",ROW()-5) -> 24 | B29: =IF(C29="","","B-"&TEXT(ROW()-5,"000")) -> B-024 | C29: كارين وليم منير | D29: بنت | E29: سنة تانية | F29: غبريال | G29: لا | H29: 01227429046 | J29: 3 شارع قباء - شقة 3 الدور 3 - اخر مختار اباظة - قباء | M29: نشط | N29: =IF(O29="","",F29&"|"&O29) -> غبريال|24 | O29: =IF(OR(C29="",F29=""),"",COUNTIFS(F$6:F29,F29,C$6:C29,"<>")) -> 24 | P29: =IF($O29="","",IFERROR(CHOOSE(MATCH($F29,الإعدادات!$B$4:$B$7,0),INDEX('حضور سوريال'!$C$7:$C$36,$O29),INDEX('حضور غبريال'!$C$7:$C$36,$O29),INDEX('حضور رفائيل'!$C$7:$C$36,$O29),INDEX('حضور ميخائيل'!$C$7:$C$36,$O29)),"")) -> 0 | Q29: =IF($O29="","",IFERROR(CHOOSE(MATCH($F29,الإعدادات!$B$4:$B$7,0),INDEX('حضور سوريال'!$D$7:$D$36,$O29),INDEX('حضور غبريال'!$D$7:$D$36,$O29),INDEX('حضور رفائيل'!$D$7:$D$36,$O29),INDEX('حضور ميخائيل'!$D$7:$D$36,$O29)),"")) -> 0 | R29: =IF($O29="","",IFERROR(CHOOSE(MATCH($F29,الإعدادات!$B$4:$B$7,0),INDEX('حضور سوريال'!$F$7:$F$36,$O29),INDEX('حضور غبريال'!$F$7:$F$36,$O29),INDEX('حضور رفائيل'!$F$7:$F$36,$O29),INDEX('حضور ميخائيل'!$F$7:$F$36,$O29)),"")) | S29: =IF($O29="","",IFERROR(CHOOSE(MATCH($F29,الإعدادات!$B$4:$B$7,0),INDEX('حضور سوريال'!$G$7:$G$36,$O29),INDEX('حضور غبريال'!$G$7:$G$36,$O29),INDEX('حضور رفائيل'!$G$7:$G$36,$O29),INDEX('حضور ميخائيل'!$G$7:$G$36,$O29)),"")) -> 0 | T29: =IF($O29="","",IFERROR(CHOOSE(MATCH($F29,الإعدادات!$B$4:$B$7,0),INDEX('حضور سوريال'!$H$7:$H$36,$O29),INDEX('حضور غبريال'!$H$7:$H$36,$O29),INDEX('حضور رفائيل'!$H$7:$H$36,$O29),INDEX('حضور ميخائيل'!$H$7:$H$36,$O29)),"")) -> — | U29: =IF($O29="","",IFERROR(CHOOSE(MATCH($F29,الإعدادات!$B$4:$B$7,0),INDEX('حضور سوريال'!$I$7:$I$36,$O29),INDEX('حضور غبريال'!$I$7:$I$36,$O29),INDEX('حضور رفائيل'!$I$7:$I$36,$O29),INDEX('حضور ميخائيل'!$I$7:$I$36,$O29)),"")) -> ⏳ لسه مفيش حضور | V29: =IF($O29="","",IFERROR(CHOOSE(MATCH($F29,الإعدادات!$B$4:$B$7,0),INDEX('حضور سوريال'!$BM$7:$BM$36,$O29),INDEX('حضور غبريال'!$BM$7:$BM$36,$O29),INDEX('حضور رفائيل'!$BM$7:$BM$36,$O29),INDEX('حضور ميخائيل'!$BM$7:$BM$36,$O29)),"")) -> 0 | W29: =IF(OR(V29=3,V29=4),COUNTIFS(V$6:V29,3)+COUNTIFS(V$6:V29,4),"")
